Workbook
Name Discount: 'Quarter Effect Worksheet'!$A$36:$A$41

Sheet Proforma _Summary
B2: 2017-2022 Proforma
B6: Projected Financial Performance (in US$) | E6: 2017 | F6: 2018 | G6: 2019 | H6: 2020 | I6: 2021 | J6: 2022
C8: Total number of Customers (Registered Users) | E8: 0 | F8: ='Assumptions & Sensitivity'!L13+'Assumptions & Sensitivity'!L30 -> 0 | G8: =SUM('Assumptions & Sensitivity'!P13)+SUM('Assumptions & Sensitivity'!P30) -> 236340 | H8: =SUM('Assumptions & Sensitivity'!T13)+SUM('Assumptions & Sensitivity'!T30) -> 1055661 | I8: =SUM('Assumptions & Sensitivity'!X13)+SUM('Assumptions & Sensitivity'!X30) -> 3536128 | J8: =SUM('Assumptions & Sensitivity'!AB13)+SUM('Assumptions & Sensitivity'!AB30) -> 7943561
C9: Total number of orders assisted | E9: 0 | F9: =SUM('Assumptions & Sensitivity'!I17:L17)+SUM('Assumptions & Sensitivity'!I34:L34) -> 0 | G9: =SUM('Assumptions & Sensitivity'!M17:P17)+SUM('Assumptions & Sensitivity'!M34:P34) -> 223447 | H9: =SUM('Assumptions & Sensitivity'!Q17:T17)+SUM('Assumptions & Sensitivity'!Q34:T34) -> 1066967 | I9: =SUM('Assumptions & Sensitivity'!U17:X17)+SUM('Assumptions & Sensitivity'!U34:X34) -> 3983256 | J9: =SUM('Assumptions & Sensitivity'!Y17:AB17)+SUM('Assumptions & Sensitivity'!Y34:AB34) -> 9870612
C10: Projected GMV generated(in US$) | E10: 0 | F10: =SUM('Assumptions & Sensitivity'!I19:L19)+SUM('Assumptions & Sensitivity'!I36:L36) -> 0 | G10: =SUM('Assumptions & Sensitivity'!M19:P19)+SUM('Assumptions & Sensitivity'!M36:P36) -> 21674359 | H10: =SUM('Assumptions & Sensitivity'!Q19:T19)+SUM('Assumptions & Sensitivity'!Q36:T36) -> 103495799 | I10: =SUM('Assumptions & Sensitivity'!U19:X19)+SUM('Assumptions & Sensitivity'!U36:X36) -> 386375832 | J10: =SUM('Assumptions & Sensitivity'!Y19:AB19)+SUM('Assumptions & Sensitivity'!Y36:AB36) -> 984354507
C12: Net Revenue | E12: 0 | F12: ='P&L'!N3 -> 0 | G12: ='P&L'!S3 -> 1265714.2 | H12: ='P&L'!X3 -> 6043829.4 | I12: ='P&L'!AC3 -> 22563136 | J12: ='P&L'!AH3 -> 57483213
C13: Cost of Goods Sold (Tech Expenses) | E13: =SUM('Assumptions & Sensitivity'!E57:H57) -> 12788.22 | F13: =SUM('Assumptions & Sensitivity'!I57:L57) -> 58722.5 | G13: =SUM('Assumptions & Sensitivity'!M57:P57) -> 235642.1 | H13: =SUM('Assumptions & Sensitivity'!Q57:T57) -> 771210.24 | I13: =SUM('Assumptions & Sensitivity'!U57:X57) -> 2233425.6 | J13: =SUM('Assumptions & Sensitivity'!Y57:AB57) -> 5074707.7 | K13: =J13/$J$12 -> 0.088281561
C14: Gross Margin | E14: =E12-E13 -> -12788.22 | F14: =F12-F13 -> -58722.5 | G14: =G12-G13 -> 1030072.1 | H14: =H12-H13 -> 5272619.2 | I14: =I12-I13 -> 20329710 | J14: =J12-J13 -> 52408505
C16: Operating Expenses
D17: Compensation (ex.Marketing) | E17: =SUM(E18:E19) -> 38000 | F17: =SUM(F18:F19) -> 387000 | G17: =SUM(G18:G19) -> 561825 | H17: =SUM(H18:H19) -> 1373557.5 | I17: =SUM(I18:I19) -> 2355424.9 | J17: =SUM(J18:J19) -> 2494157 | K17: =J17/$J$12 -> 0.043389312
D18: Comp Tech | E18: =SUM('Hiring Plan'!D105:G105) -> 38000 | F18: =SUM('Hiring Plan'!H105:K105) -> 337000 | G18: =SUM('Hiring Plan'!L108:O108) -> 201825 | H18: =SUM('Hiring Plan'!P105:S105) -> 890857.5 | I18: =SUM('Hiring Plan'!T105:W105) -> 1533634 | J18: =SUM('Hiring Plan'!X105:AA105) -> 1533634 | K18: =J18/$J$12 -> 0.026679685
D19: Comp Other | E19: =SUM('Hiring Plan'!D101:G101)+SUM('Hiring Plan'!D129:G129)+SUM('Hiring Plan'!D132:G132)+SUM('Hiring Plan'!D135:G136)+SUM('Hiring Plan'!D141:G141) -> 0 | F19: =SUM('Hiring Plan'!H101:K101)+SUM('Hiring Plan'!H129:K129)+SUM('Hiring Plan'!H132:K132)+SUM('Hiring Plan'!H135:K136)+SUM('Hiring Plan'!H141:K141) -> 50000 | G19: =SUM('Hiring Plan'!L101:O101)+SUM('Hiring Plan'!L129:O129)+SUM('Hiring Plan'!L132:O132)+SUM('Hiring Plan'!L135:O136)+SUM('Hiring Plan'!L141:O141) -> 360000 | H19: =SUM('Hiring Plan'!P101:S101)+SUM('Hiring Plan'!P129:S129)+SUM('Hiring Plan'!P132:S132)+SUM('Hiring Plan'!P135:S136)+SUM('Hiring Plan'!P141:S141) -> 482700 | I19: =SUM('Hiring Plan'!T101:W101)+SUM('Hiring Plan'!T129:W129)+SUM('Hiring Plan'!T132:W132)+SUM('Hiring Plan'!T135:W136)+SUM('Hiring Plan'!T141:W141) -> 821790.88 | J19: =SUM('Hiring Plan'!X101:AA101)+SUM('Hiring Plan'!X129:AA129)+SUM('Hiring Plan'!X132:AA132)+SUM('Hiring Plan'!X135:AA136)+SUM('Hiring Plan'!X141:AA141) -> 960523 | K19: =J19/$J$12 -> 0.016709626
D20: Outsourcing - Contractors | E20: =SUM('Assumptions & Sensitivity'!E49:H49) -> 33049.37 | F20: =SUM('Assumptions & Sensitivity'!I49:L49) -> 95203.125 | G20: =SUM('Assumptions & Sensitivity'!M49:P49) -> 52792.5 | H20: =SUM('Assumptions & Sensitivity'!Q49:T49) -> 53444.55 | I20: =SUM('Assumptions & Sensitivity'!U49:X49) -> 34162.5 | J20: =SUM('Assumptions & Sensitivity'!Y49:AB49) -> 34162.5 | K20: =J20/$J$12 -> 0.00059430394
D21: Office Rent, Utilities & Maintenance | E21: =SUM('Assumptions & Sensitivity'!E50:H50) -> 3683.95 | F21: =SUM('Assumptions & Sensitivity'!I50:L50) -> 57120 | G21: =SUM('Assumptions & Sensitivity'!M50:P50) -> 117096 | H21: =SUM('Assumptions & Sensitivity'!Q50:T50) -> 184426.2 | I21: =SUM('Assumptions & Sensitivity'!U50:X50) -> 193647.51 | J21: =SUM('Assumptions & Sensitivity'!Y50:AB50) -> 198535.93 | K21: =J21/$J$12 -> 0.0034538071
D22: AI Training | E22: =SUM('Assumptions & Sensitivity'!E67:H67) -> 0 | F22: =SUM('Assumptions & Sensitivity'!I67:L67) -> 272987.5 | G22: =SUM('Assumptions & Sensitivity'!M67:P67) -> 266719.5 | H22: =SUM('Assumptions & Sensitivity'!Q67:T67) -> 275955.88 | I22: =SUM('Assumptions & Sensitivity'!U67:X67) -> 154755.88 | J22: =SUM('Assumptions & Sensitivity'!Y67:AB67) -> 270832.79 | K22: =J22/$J$12 -> 0.0047115109
D23: Software Subscriptions | E23: =SUM('Assumptions & Sensitivity'!E71:H71) -> 1902.54 | F23: =SUM('Assumptions & Sensitivity'!I71:L71) -> 5200 | G23: =SUM('Assumptions & Sensitivity'!M71:P71) -> 8550 | H23: =SUM('Assumptions & Sensitivity'!Q71:T71) -> 15300 | I23: =SUM('Assumptions & Sensitivity'!U71:X71) -> 25842 | J23: =SUM('Assumptions & Sensitivity'!Y71:AB71) -> 27642 | K23: =J23/$J$12 -> 0.00048087083
D24: Equipment Lease (computers, desks) | E24: =SUM('Assumptions & Sensitivity'!E72:H72) -> 0 | F24: =SUM('Assumptions & Sensitivity'!I72:L72) -> 1800 | G24: =SUM('Assumptions & Sensitivity'!M72:P72) -> 5600 | H24: =SUM('Assumptions & Sensitivity'!Q72:T72) -> 8500 | I24: =SUM('Assumptions & Sensitivity'!U72:X72) -> 15821 | J24: =SUM('Assumptions & Sensitivity'!Y72:AB72) -> 18428 | K24: =J24/$J$12 -> 0.00032058055
D25: Legal Fees | E25: =SUM('Assumptions & Sensitivity'!E73:H73) -> 64404.04 | F25: =SUM('Assumptions & Sensitivity'!I73:L73) -> 50000 | G25: =SUM('Assumptions & Sensitivity'!M73:P73) -> 60000 | H25: =SUM('Assumptions & Sensitivity'!Q73:T73) -> 100000 | I25: =SUM('Assumptions & Sensitivity'!U73:X73) -> 120000 | J25: =SUM('Assumptions & Sensitivity'!Y73:AB73) -> 120010 | K25: =J25/$J$12 -> 0.00208774
D26: Marketing Expenses (inc. Comp) | E26: =SUM('Assumptions & Sensitivity'!E74:H74)+E27 -> 129.99 | F26: =SUM('Assumptions & Sensitivity'!I74:L74)+F27 -> 125000 | G26: =SUM('Assumptions & Sensitivity'!M74:P74)+G27 -> 500000 | H26: =SUM('Assumptions & Sensitivity'!Q74:T74)+H27 -> 2053648.8 | I26: =SUM('Assumptions & Sensitivity'!U74:X74)+I27 -> 7324030.3 | J26: =SUM('Assumptions & Sensitivity'!Y74:AB74)+J27 -> 17900053 | K26: =J26/$J$12 -> 0.31139619
D27: Comp Marketing | E27: =SUM('Hiring Plan'!D118:G118) -> 0 | F27: =SUM('Hiring Plan'!H118:K118) -> 50000 | G27: =SUM('Hiring Plan'!L118:O118) -> 100000 | H27: =SUM('Hiring Plan'!P118:S118) -> 240500 | I27: =SUM('Hiring Plan'!T118:W118) -> 555089.5 | J27: =SUM('Hiring Plan'!X118:AA118) -> 655089.5 | K27: =J27/$J$12 -> 0.011396188
D28: Travel & Entertainment | E28: =SUM('Assumptions & Sensitivity'!E75:H75) -> 20603.74 | F28: =SUM('Assumptions & Sensitivity'!I75:L75) -> 22000 | G28: =SUM('Assumptions & Sensitivity'!M75:P75) -> 40000 | H28: =SUM('Assumptions & Sensitivity'!Q75:T75) -> 130000 | I28: =SUM('Assumptions & Sensitivity'!U75:X75) -> 200000 | J28: =SUM('Assumptions & Sensitivity'!Y75:AB75) -> 200010 | K28: =J28/$J$12 -> 0.0034794506
D29: Misc. Expenses | E29: =SUM('Assumptions & Sensitivity'!E76:H76) -> 19011.65 | F29: =SUM('Assumptions & Sensitivity'!I76:L76) -> 20000 | G29: =SUM('Assumptions & Sensitivity'!M76:P76) -> 12657.142 | H29: =SUM('Assumptions & Sensitivity'!Q76:T76) -> 60438.294 | I29: =SUM('Assumptions & Sensitivity'!U76:X76) -> 225631.36 | J29: =SUM('Assumptions & Sensitivity'!Y76:AB76) -> 574832.13 | K29: =J29/$J$12 -> 0.01
E30: =E17+SUM(E20:E26)+E28+E29 -> 180785.28 | F30: =F17+SUM(F20:F26)+F28+F29 -> 1036310.6 | G30: =G17+SUM(G20:G26)+G28+G29 -> 1625240.1 | H30: =H17+SUM(H20:H26)+H28+H29 -> 4255271.3 | I30: =I17+SUM(I20:I26)+I28+I29 -> 10649315 | J30: =J17+SUM(J20:J26)+J28+J29 -> 21838664
C32: Operating Income (Loss) | E32: =E14-E30 -> -193573.5 | F32: =F14-F30 -> -1095033.1 | G32: =G14-G30 -> -595168.04 | H32: =H14-H30 -> 1017347.9 | I32: =I14-I30 -> 9680395 | J32: =J14-J30 -> 30569841 | K32: =J32/$J$12 -> 0.53180468
C34: Operating Ratios as a percent of Sales
D35: Total Expenses | E35: NA | F35: NA | G35: =G30/G12 -> 1.2840499 | H35: =H30/H12 -> 0.70406872 | I35: =I30/I12 -> 0.47197852 | J35: =J30/J12 -> 0.37991376
D36: Marketing Expenses | E36: NA | F36: NA | G36: =G26/G12 -> 0.39503389 | H36: =H26/H12 -> 0.33979265 | I36: =I26/I12 -> 0.32460161 | J36: =J26/J12 -> 0.31139619
D37: Gross Margin | E37: NA | F37: NA | G37: =G14/G12 -> 0.81382677 | H37: =H14/H12 -> 0.87239709 | I37: =I14/I12 -> 0.9010144 | J37: =J14/J12 -> 0.91171844
D38: Operating Margin | E38: NA | F38: NA | G38: =G32/G12 -> -0.47022309 | H38: =H32/H12 -> 0.16832837 | I38: =I32/I12 -> 0.42903588 | J38: =J32/J12 -> 0.53180468
B42: Use of Funds
D44: 18 months
D45: Tech Hires | E45: =SUM('Hiring Plan'!J105:O105) -> 813025 | F45: =E45/$E$54 -> 0.25817568
D46: Non-Tech Hires | E46: =SUM('Hiring Plan'!J144:O144)-SUM('Hiring Plan'!J105:O105)-SUM('Hiring Plan'!J118:O118) -> 410000 | F46: =E46/$E$54 -> 0.13019529
D47: Marketing | E47: =SUM('Assumptions & Sensitivity'!K74:P74)+SUM('Hiring Plan'!J118:O118) -> 625000 | F47: =E47/$E$54 -> 0.19846844
D48: Technology | E48: =SUM('Assumptions & Sensitivity'!K57:P57)+SUM('Assumptions & Sensitivity'!K71:P72) -> 304514.6 | F48: =E48/$E$54 -> 0.096698458
D49: G & A | E49: =SUM('Assumptions & Sensitivity'!K78:P78) -> 338873.14 | F49: =E49/$E$54 -> 0.107609
D50: AI Training | E50: =SUM('Assumptions & Sensitivity'!K69:P69) -> 334237.5 | F50: =E50/$E$54 -> 0.10613695 | G50: =E50/SUM($E$50:$E$53) -> 0.5081894
D51: Rent & Equipment | E51: =SUM('Assumptions & Sensitivity'!K68:P68)+SUM('Assumptions & Sensitivity'!K70:P70) -> 205469.5 | F51: =E51/$E$54 -> 0.065246736 | G51: =E51/SUM($E$50:$E$53) -> 0.31240487
D52: Labor 1 | E52: =SUM('Hiring Plan'!J152:O153)+SUM('Hiring Plan'!J156:O156) -> 89730 | F52: =E52/$E$54 -> 0.028493716 | G52: =E52/SUM($E$50:$E$53) -> 0.13642944
D53: Labor 2 | E53: =SUM('Hiring Plan'!J154:O155) -> 28265.625 | F53: =E53/$E$54 -> 0.008975735 | G53: =E53/SUM($E$50:$E$53) -> 0.0429763
...

Sheet Assumptions & Sensitivity
A1: Assumptions | E1: Q1-17 | F1: Q2-17 | G1: Q3-17 | H1: Q4-17 | I1: Q1-18 | J1: Q2-18 | K1: Q3-18 | L1: Q4-18 | M1: Q1-19 | N1: Q2-19 | O1: Q3-19 | P1: Q4-19 | Q1: Q1-20 | R1: Q2-20 | S1: Q3-20 | T1: Q4-20 | U1: Q1-21 | V1: Q2-21 | W1: Q3-21 | X1: Q4-21 | Y1: Q1-22 | Z1: Q2-22 | AA1: Q3-22 | AB1: Q4-22
B3: Revenue Assumptions
B5: Revenue Stream 1 - Affiliate Marketing
C6: Women: 18-38 years
C7: Population 18 - 29 | K7: =SUM('U.S. Population'!V100:AG100) -> 26459763 | L7: =K7+(O7-K7)/4 -> 26487561 | M7: =K7+2*(O7-K7)/4 -> 26515359 | N7: =K7+3*(O7-K7)/4 -> 26543157 | O7: =SUM('U.S. Population'!V101:AG101) -> 26570955 | P7: =O7+(S7-O7)/4 -> 26577470 | Q7: =O7+2*(S7-O7)/4 -> 26583984 | R7: =O7+3*(S7-O7)/4 -> 26590499 | S7: =SUM('U.S. Population'!V102:AG102) -> 26597014 | T7: =S7+(W7-S7)/4 -> 26566608 | U7: =S7+2*(W7-S7)/4 -> 26536202 | V7: =S7+3*(W7-S7)/4 -> 26505797 | W7: =SUM('U.S. Population'!V103:AG103) -> 26475391 | X7: =W7+45000 -> 26520391 | Y7: =X7+45000 -> 26565391 | Z7: =Y7+45000 -> 26610391 | AA7: =Z7+45000 -> 26655391 | AB7: =AA7+45000 -> 26700391
C8: Population 30 - 38 | K8: =SUM('U.S. Population'!AH100:AP100) -> 19454990 | L8: =K8+(O8-K8)/4 -> 19454990 | M8: =K8+2*(O8-K8)/4 -> 19454990 | N8: =K8+3*(O8-K8)/4 -> 19454990 | O8: =SUM('U.S. Population'!AH100:AP100) -> 19454990 | P8: =O8+(S8-O8)/4 -> 19557784 | Q8: =O8+2*(S8-O8)/4 -> 19660577 | R8: =O8+3*(S8-O8)/4 -> 19763370 | S8: =SUM('U.S. Population'!AH102:AP102) -> 19866164 | T8: =S8+(W8-S8)/4 -> 19866164 | U8: =S8+2*(W8-S8)/4 -> 19866164 | V8: =S8+3*(W8-S8)/4 -> 19866164 | W8: =SUM('U.S. Population'!AH102:AP102) -> 19866164 | X8: =W8+45000 -> 19911164 | Y8: =X8+45000 -> 19956164 | Z8: =Y8+45000 -> 20001164 | AA8: =Z8+45000 -> 20046164 | AB8: =AA8+45000 -> 20091164
C9: Use Instagram or Pinterest 18 - 29 | D9: 0.6 | K9: =K7*$D$9 -> 15875858 | L9: =L7*$D$9 -> 15892537 | M9: =M7*$D$9 -> 15909215 | N9: =N7*$D$9 -> 15925894 | O9: =O7*$D$9 -> 15942573 | P9: =P7*$D$9 -> 15946482 | Q9: =Q7*$D$9 -> 15950391 | R9: =R7*$D$9 -> 15954300 | ... AB9: =AB7*$D$9 -> 16020235
C10: Use Instagram or Pinterest 30 - 38 | D10: 0.41 | K10: =K8*$D$10 -> 7976545.9 | L10: =L8*$D$10 -> 7976545.9 | M10: =M8*$D$10 -> 7976545.9 | N10: =N8*$D$10 -> 7976545.9 | O10: =O8*$D$10 -> 7976545.9 | P10: =P8*$D$10 -> 8018691.2 | Q10: =Q8*$D$10 -> 8060836.6 | R10: =R8*$D$10 -> 8102981.9 | ... AB10: =AB8*$D$10 -> 8237377.2
C11: Total User Base | K11: =K9+K10 -> 23852404 | L11: =L9+L10 -> 23869082 | M11: =M9+M10 -> 23885761 | N11: =N9+N10 -> 23902440 | O11: =O9+O10 -> 23919119 | P11: =P9+P10 -> 23965173 | Q11: =Q9+Q10 -> 24011227 | R11: =R9+R10 -> 24057281 | ... AB11: =AB9+AB10 -> 24257612
C12: Our reach | M12: 0.002 | N12: =N13/N7 -> 0.0032722181 | O12: =O13/O7 -> 0.0051176557 | P12: =P13/P7 -> 0.007466926 | Q12: =Q13/Q7 -> 0.010866392 | R12: =R13/R7 -> 0.016023618 | S12: =S13/S7 -> 0.024003296 | T12: =T13/T7 -> 0.033366134 | U12: =U13/U7 -> 0.050930272 | ... AB12: =AB13/AB7 -> 0.24981275
C13: Total number of Customers (Registered Users) | M13: =M11*M12 -> 47771.523 | N13: =ROUNDUP(M13*(1+M14),0) -> 86855 | O13: =ROUNDUP(N13*(1+N14),0) -> 135981 | P13: =ROUNDUP(O13*(1+O14),0) -> 198452 | Q13: =ROUNDUP(P13*(1+P14),0) -> 288872 | R13: =ROUNDUP(Q13*(1+Q14),0) -> 426076 | S13: =ROUNDUP(R13*(1+R14),0) -> 638416 | T13: =ROUNDUP(S13*(1+S14),0) -> 886425 | U13: =ROUNDUP(T13*(1+T14),0) -> 1351496 | ... AB13: =ROUNDUP(AA13*(1+AA14),0) -> 6670098
C14: Growth Rate (Customer Acquisition) | M14: 0.818125 | N14: 0.56560096 | O14: 0.45940318 | P14: 0.455625 | Q14: 0.47496429 | R14: 0.49836111 | S14: 0.38847527 | T14: 0.5246586 | U14: 0.3 | V14: 0.3 | W14: 0.3 | X14: 0.3 | Y14: 0.2 | Z14: 0.2 | AA14: 0.2 | AB14: 0
C15: Avg. shopping instances | D15: 4 | E15: per quarter per Woman | R15: =R13/N13-1 -> 3.9056013 | V15: =V13/R13-1 -> 3.1235484
C16: Avg. orders assisted (in %) | M16: 0.1 | N16: 0.1 | O16: 0.1 | P16: 0.1 | Q16: 0.1 | R16: 0.1 | S16: 0.1 | T16: 0.1 | U16: 0.1 | V16: 0.1 | W16: 0.1 | X16: 0.1 | Y16: 0.1 | Z16: 0.1 | AA16: 0.1 | AB16: 0.1
C17: Total number of orders assisted | M17: =ROUNDUP(M13*($D$15*M16),0) -> 19109 | N17: =ROUNDUP(N13*($D$15*N16),0) -> 34742 | O17: =ROUNDUP(O13*($D$15*O16),0) -> 54393 | P17: =ROUNDUP(P13*($D$15*P16),0) -> 79381 | Q17: =ROUNDUP(Q13*($D$15*Q16),0) -> 115549 | R17: =ROUNDUP(R13*($D$15*R16),0) -> 170431 | S17: =ROUNDUP(S13*($D$15*S16),0) -> 255367 | T17: =ROUNDUP(T13*($D$15*T16),0) -> 354570 | ... AB17: =ROUNDUP(AB13*($D$15*AB16),0) -> 2668040
C18: Average Order Value, AOV (in US$) | M18: 97 | N18: 97 | O18: 97 | P18: 97 | Q18: 97 | R18: 97 | S18: 97 | T18: 97 | U18: 97 | V18: 97 | W18: 97 | X18: 97 | Y18: 98 | Z18: 99 | AA18: 100 | AB18: 101
C19: Projected GMV generated(in US$) | M19: =M18*M17 -> 1853573 | N19: =N18*N17 -> 3369974 | O19: =O18*O17 -> 5276121 | P19: =P18*P17 -> 7699957 | Q19: =Q18*Q17 -> 11208253 | R19: =R18*R17 -> 16531807 | S19: =S18*S17 -> 24770599 | T19: =T18*T17 -> 34393290 | ... AB19: =AB18*AB17 -> 269472040
C20: Average Commission Rate (%) | M20: 0.06 | N20: 0.06 | O20: 0.06 | P20: 0.06 | Q20: 0.06 | R20: 0.06 | S20: 0.06 | T20: 0.06 | U20: 0.06 | V20: 0.06 | W20: 0.06 | X20: 0.06 | Y20: 0.06 | Z20: 0.06 | AA20: 0.06 | AB20: 0.06
C21: Revenue - Women | M21: =M20*M19 -> 111214.38 | N21: =N20*N19 -> 202198.44 | O21: =O20*O19 -> 316567.26 | P21: =P20*P19 -> 461997.42 | Q21: =Q20*Q19 -> 672495.18 | R21: =R20*R19 -> 991908.42 | S21: =S20*S19 -> 1486235.9 | T21: =T20*T19 -> 2063597.4 | ... AB21: =AB20*AB19 -> 16168322
C23: Men: 18-38 years
C24: Population 18 - 29 | K24: =SUM('U.S. Population'!V53:AG53) -> 27756248 | L24: =K24+(O24-K24)/4 -> 27789971 | M24: =K24+2*(O24-K24)/4 -> 27823694 | N24: =K24+3*(O24-K24)/4 -> 27857416 | O24: =SUM('U.S. Population'!V54:AG54) -> 27891139 | P24: =O24+(S24-O24)/4 -> 27899573 | Q24: =O24+2*(S24-O24)/4 -> 27908008 | R24: =O24+3*(S24-O24)/4 -> 27916442 | S24: =SUM('U.S. Population'!V55:AG55) -> 27924876 | T24: =S24+(W24-S24)/4 -> 27894138 | U24: =S24+2*(W24-S24)/4 -> 27863400 | V24: =S24+3*(W24-S24)/4 -> 27832662 | W24: =SUM('U.S. Population'!V56:AG56) -> 27801924 | X24: =W24+(48744844-W24)/4 -> 33037654 | Y24: =X24+(48744844-X24)/4 -> 36964452 | Z24: =Y24+(48744844-Y24)/4 -> 39909550 | AA24: =Z24+(48744844-Z24)/4 -> 42118373 | AB24: =AA24+(48744844-AA24)/4 -> 43774991
C25: Population 30 - 38 | K25: =SUM('U.S. Population'!AH55:AP55) -> 20314925 | L25: =K25+(O25-K25)/4 -> 20314925 | M25: =K25+2*(O25-K25)/4 -> 20314925 | N25: =K25+3*(O25-K25)/4 -> 20314925 | O25: =SUM('U.S. Population'!AH55:AP55) -> 20314925 | P25: =O25+(S25-O25)/4 -> 20410855 | Q25: =O25+2*(S25-O25)/4 -> 20506786 | R25: =O25+3*(S25-O25)/4 -> 20602716 | S25: =SUM('U.S. Population'!AH56:AP56) -> 20698646 | T25: =S25+(W25-S25)/4 -> 20792462 | U25: =S25+2*(W25-S25)/4 -> 20886278 | V25: =S25+3*(W25-S25)/4 -> 20980093 | W25: =SUM('U.S. Population'!AH57:AP57) -> 21073909 | X25: =W25+(SUM('U.S. Population'!AH57:AP57)-W25)/4 -> 21073909 | Y25: =X25+(SUM('U.S. Population'!AI57:AQ57)-X25)/4 -> 20997930 | Z25: =Y25+(SUM('U.S. Population'!AJ57:AR57)-Y25)/4 -> 20860768 | AA25: =Z25+(SUM('U.S. Population'!AK57:AS57)-Z25)/4 -> 20713811 | AB25: =AA25+(SUM('U.S. Population'!AL57:AT57)-AA25)/4 -> 20538811
C26: Use Instagram or Pinterest 18 - 29 | D26: 0.4 | L26: =L24*$D$26 -> 11115988 | M26: =M24*$D$26 -> 11129477 | N26: =N24*$D$26 -> 11142966 | O26: =O24*$D$26 -> 11156456 | P26: =P24*$D$26 -> 11159829 | Q26: =Q24*$D$26 -> 11163203 | R26: =R24*$D$26 -> 11166577 | S26: =S24*$D$26 -> 11169950 | ... AB26: =AB24*$D$26 -> 17509996
C27: Use Instagram or Pinterest 30 - 38 | D27: 0.35 | L27: =L25*$D$27 -> 7110223.8 | M27: =M25*$D$27 -> 7110223.8 | N27: =N25*$D$27 -> 7110223.8 | O27: =O25*$D$27 -> 7110223.8 | P27: =P25*$D$27 -> 7143799.3 | Q27: =Q25*$D$27 -> 7177374.9 | R27: =R25*$D$27 -> 7210950.5 | S27: =S25*$D$27 -> 7244526.1 | ... AB27: =AB25*$D$27 -> 7188583.8
C28: Total User Base | L28: =L26+L27 -> 18226212 | M28: =M26+M27 -> 18239701 | N28: =N26+N27 -> 18253190 | O28: =O26+O27 -> 18266679 | P28: =P26+P27 -> 18303629 | Q28: =Q26+Q27 -> 18340578 | R28: =R26+R27 -> 18377527 | S28: =S26+S27 -> 18414476 | ... AB28: =AB26+AB27 -> 24698580
C29: Our reach | M29: =M12/4 -> 0.0005 | N29: =N30/N24 -> 0.00059524544 | O29: =O30/O24 -> 0.00093079741 | P29: =P30/P24 -> 0.0013580136 | Q29: =Q30/Q24 -> 0.0019761712 | R29: =R30/R24 -> 0.00291391 | S29: =S30/S24 -> 0.0043647821 | T29: =T30/T24 -> 0.0060670812 | U29: =U30/U24 -> 0.0092604635 | ... AB29: =AB30/AB24 -> 0.029091108
C30: Total number of Customers (Registered Users) | M30: =M28*M29 -> 9119.8506 | N30: =ROUNDUP(M30*(1+M31),0) -> 16582 | O30: =ROUNDUP(N30*(1+N31),0) -> 25961 | P30: =ROUNDUP(O30*(1+O31),0) -> 37888 | Q30: =ROUNDUP(P30*(1+P31),0) -> 55151 | R30: =ROUNDUP(Q30*(1+Q31),0) -> 81346 | S30: =ROUNDUP(R30*(1+R31),0) -> 121886 | T30: =ROUNDUP(S30*(1+S31),0) -> 169236 | U30: =ROUNDUP(T30*(1+T31),0) -> 258028 | ... AB30: =ROUNDUP(AA30*(1+AA31),0) -> 1273463
C31: Growth Rate (Customer Acquisition) | M31: =M14 -> 0.818125 | N31: =N14 -> 0.56560096 | O31: =O14 -> 0.45940318 | P31: =P14 -> 0.455625 | Q31: =Q14 -> 0.47496429 | R31: =R14 -> 0.49836111 | S31: =S14 -> 0.38847527 | T31: =T14 -> 0.5246586 | ... AB31: =AB14 -> 0
C32: Avg. shopping instances | D32: 2 | E32: per quarter per Man
C33: Avg. orders assisted by Woolly (in %) | M33: 0.1 | N33: 0.1 | O33: 0.1 | P33: 0.1 | Q33: 0.1 | R33: 0.1 | S33: 0.1 | T33: 0.1 | U33: 0.1 | V33: 0.1 | W33: 0.1 | X33: 0.1 | Y33: 0.1 | Z33: 0.1 | AA33: 0.1 | AB33: 0.1
C34: Total number of orders assisted | M34: =ROUNDUP(M30*($D$15*M33),0) -> 3648 | N34: =ROUNDUP(N30*($D$15*N33),0) -> 6633 | O34: =ROUNDUP(O30*($D$15*O33),0) -> 10385 | P34: =ROUNDUP(P30*($D$15*P33),0) -> 15156 | Q34: =ROUNDUP(Q30*($D$15*Q33),0) -> 22061 | R34: =ROUNDUP(R30*($D$15*R33),0) -> 32539 | S34: =ROUNDUP(S30*($D$15*S33),0) -> 48755 | T34: =ROUNDUP(T30*($D$15*T33),0) -> 67695 | ... AB34: =ROUNDUP(AB30*($D$15*AB33),0) -> 509386
C35: Average Order Value, AOV (in US$) | M35: 97 | N35: 97 | O35: 97 | P35: 97 | Q35: 97 | R35: 97 | S35: 97 | T35: 97 | U35: 97 | V35: 97 | W35: 97 | X35: 97 | Y35: 98 | Z35: 99 | AA35: 100 | AB35: 101
C36: Projected GMV generated (in US$) | M36: =M35*M34 -> 353856 | N36: =N35*N34 -> 643401 | O36: =O35*O34 -> 1007345 | P36: =P35*P34 -> 1470132 | Q36: =Q35*Q34 -> 2139917 | R36: =R35*R34 -> 3156283 | S36: =S35*S34 -> 4729235 | T36: =T35*T34 -> 6566415 | ... AB36: =AB35*AB34 -> 51447986
C37: Average Commission Rate (%) | M37: 0.05 | N37: 0.05 | O37: 0.05 | P37: 0.05 | Q37: 0.05 | R37: 0.05 | S37: 0.05 | T37: 0.05 | U37: 0.05 | V37: 0.05 | W37: 0.05 | X37: 0.05 | Y37: 0.05 | Z37: 0.05 | AA37: 0.05 | AB37: 0.05
C38: Revenue - Men | K38: =K37*K36 -> 0 | L38: =L37*L36 -> 0 | M38: =M37*M36 -> 17692.8 | N38: =N37*N36 -> 32170.05 | O38: =O37*O36 -> 50367.25 | P38: =P37*P36 -> 73506.6 | Q38: =Q37*Q36 -> 106995.85 | R38: =R37*R36 -> 157814.15 | ... AB38: =AB37*AB36 -> 2572399.3
C40: Total number of Registered Users | K40: =J30+K13 -> 0 | L40: =K30+L13 -> 0 | M40: =M30+M13 -> 56891.373 | N40: =N30+N13 -> 103437 | O40: =O30+O13 -> 161942 | P40: =P30+P13 -> 236340 | Q40: =Q30+Q13 -> 344023 | R40: =R30+R13 -> 507422 | S40: =S30+S13 -> 760302 | T40: =T30+T13 -> 1055661 | ... AB40: =AB30+AB13 -> 7943561
C41: Total Projected GMV (in US$) | K41: =J36+K19 -> 0 | L41: =K36+L19 -> 0 | M41: =M36+M19 -> 2207429 | N41: =N36+N19 -> 4013375 | O41: =O36+O19 -> 6283466 | P41: =P36+P19 -> 9170089 | Q41: =Q36+Q19 -> 13348170 | R41: =R36+R19 -> 19688090 | S41: =S36+S19 -> 29499834 | T41: =T36+T19 -> 40959705 | ... AB41: =AB36+AB19 -> 320920026
C42: Total Projected Revenues - Affiliate Marketing (in US$) | K42: =K21+J38 -> 0 | L42: =L21+K38 -> 0 | M42: =M21+M38 -> 128907.18 | N42: =N21+N38 -> 234368.49 | O42: =O21+O38 -> 366934.51 | P42: =P21+P38 -> 535504.02 | Q42: =Q21+Q38 -> 779491.03 | R42: =R21+R38 -> 1149722.6 | S42: =S21+S38 -> 1722697.7 | T42: =T21+T38 -> 2391918.1 | ... AB42: =AB21+AB38 -> 18740722
B44: Total Projected Revenues (in US$) | K44: =K42 -> 0 | L44: =L42 -> 0 | M44: =M42 -> 128907.18 | N44: =N42 -> 234368.49 | O44: =O42 -> 366934.51 | P44: =P42 -> 535504.02 | Q44: =Q42 -> 779491.03 | R44: =R42 -> 1149722.6 | ... AB44: =AB42 -> 18740722
B46: Expense Assumptions
...

Sheet Hiring Plan
B2: Hiring Plan | D2: Q1-17 | E2: Q2-17 | F2: Q3-17 | G2: Q4-17 | H2: Q1-18 | I2: Q2-18 | J2: Q3-18 | K2: Q4-18 | L2: Q1-19 | M2: Q2-19 | N2: Q3-19 | O2: Q4-19 | P2: Q1-20 | Q2: Q2-20 | R2: Q3-20 | S2: Q4-20 | T2: Q1-21 | U2: Q2-21 | V2: Q3-21 | W2: Q4-21 | X2: Q4-22 | Y2: Q4-23 | Z2: Q4-24 | AA2: Q4-25
B4: Salary Inflation (annual) - 2018 onwards | D4: 0.035
B6: Quarterly Wages (in US$)
C7: Administration
C8: CEO | D8: 0 | E8: 0 | F8: 0 | G8: 0 | H8: 0 | I8: 0 | J8: 12500 | K8: =J8 -> 12500 | L8: 35000 | M8: =L8 -> 35000 | N8: =M8 -> 35000 | O8: =N8 -> 35000 | P8: =L8*(1+$D$4) -> 36225 | Q8: =$P$8 -> 36225 | R8: =$P$8 -> 36225 | S8: =$P$8 -> 36225 | T8: =P8*(1+$D$4) -> 37492.875 | U8: =$P$8 -> 36225 | V8: =$P$8 -> 36225 | W8: =$P$8 -> 36225 | X8: =$P$8 -> 36225 | Y8: =$P$8 -> 36225 | Z8: =$P$8 -> 36225 | AA8: =$P$8 -> 36225
C9: CPO | D9: 0 | E9: 0 | F9: 0 | G9: 0 | H9: 0 | I9: 0 | J9: 12500 | K9: =J9 -> 12500 | L9: 40000 | M9: =L9 -> 40000 | N9: =M9 -> 40000 | O9: =N9 -> 40000 | P9: =L9*(1+$D$4) -> 41400 | Q9: =P9 -> 41400 | R9: =Q9 -> 41400 | S9: =R9 -> 41400 | T9: =P9*(1+$D$4) -> 42849 | U9: =T9 -> 42849 | V9: =U9 -> 42849 | W9: =V9 -> 42849 | X9: =W9 -> 42849 | Y9: =X9 -> 42849 | Z9: =Y9 -> 42849 | AA9: =Z9 -> 42849
C10: EA | D10: 0 | E10: 0 | F10: 0 | G10: 0 | H10: 0 | I10: 0 | J10: 0 | K10: 0 | L10: 0 | M10: =L10 -> 0 | N10: =M10 -> 0 | O10: =N10 -> 0 | P10: =M10*(1+$D$4) -> 0 | Q10: =P10 -> 0 | R10: =Q10 -> 0 | S10: =R10 -> 0 | T10: =P10*(1+$D$4) -> 0 | U10: =T10 -> 0 | V10: =U10 -> 0 | W10: =V10 -> 0 | X10: =W10 -> 0 | Y10: =X10 -> 0 | Z10: =Y10 -> 0 | AA10: =Z10 -> 0
C11: Technology
C12: Director - Engineering | D12: 0 | E12: 0 | F12: 0 | G12: 0 | H12: =G12 -> 0 | I12: =H12 -> 0 | J12: =I12 -> 0 | K12: =J12 -> 0 | L12: =K12*(1+$D$4) -> 0 | M12: =L12 -> 0 | N12: =M12 -> 0 | O12: =N12 -> 0 | P12: 0 | Q12: =P12 -> 0 | R12: =Q12 -> 0 | S12: =R12 -> 0 | T12: 0 | U12: =T12 -> 0 | V12: =U12 -> 0 | W12: =V12 -> 0 | X12: =W12 -> 0 | Y12: =X12 -> 0 | Z12: =Y12 -> 0 | AA12: =Z12 -> 0
C13: AI Engineer(s) | D13: 0 | E13: 0 | F13: 0 | G13: 0 | H13: 0 | I13: 0 | J13: 40000 | K13: =J13 -> 40000 | L13: =K13*(D4+1) -> 41400 | M13: =L13 -> 41400 | N13: =M13 -> 41400 | O13: =N13 -> 41400 | P13: =O13*($D$4+1) -> 42849 | Q13: =P13 -> 42849 | R13: =Q13 -> 42849 | S13: =R13 -> 42849 | T13: =P13*(1+$D$4) -> 44348.715 | U13: =T13 -> 44348.715 | V13: =U13 -> 44348.715 | W13: =V13 -> 44348.715 | X13: =W13 -> 44348.715 | Y13: =X13 -> 44348.715 | Z13: =Y13 -> 44348.715 | AA13: =Z13 -> 44348.715
C14: AI Engineer Hires | D14: 0 | E14: 0 | F14: =E14 -> 0 | G14: =F14 -> 0 | H14: =G14 -> 0 | I14: =H14 -> 0 | J14: 2 | K14: 2 | L14: 2 | M14: 2 | N14: 2 | O14: =N14 -> 2 | P14: =O14 -> 2 | Q14: =P14 -> 2 | R14: 3 | S14: =R14 -> 3 | T14: 4 | U14: =T14 -> 4 | V14: =U14 -> 4 | W14: =V14 -> 4 | X14: =W14 -> 4 | Y14: =X14 -> 4 | Z14: =Y14 -> 4 | AA14: =Z14 -> 4
C15: Engineer(s) | D15: 0 | E15: 0 | F15: 0 | G15: 0 | H15: =G15 -> 0 | I15: =H15 -> 0 | J15: 30000 | K15: =J15 -> 30000 | L15: =K15*(1+$D$4) -> 31050 | M15: =L15 -> 31050 | N15: =M15 -> 31050 | O15: =N15 -> 31050 | P15: =O15*(1+$D$4) -> 32136.75 | Q15: =P15 -> 32136.75 | R15: =Q15 -> 32136.75 | S15: =R15 -> 32136.75 | T15: =P15*(1+$D$4) -> 33261.536 | U15: =T15 -> 33261.536 | V15: =U15 -> 33261.536 | W15: =V15 -> 33261.536 | X15: =W15 -> 33261.536 | Y15: =X15 -> 33261.536 | Z15: =Y15 -> 33261.536 | AA15: =Z15 -> 33261.536
C16: Engineers Hires | D16: 0 | E16: 0 | F16: 0 | G16: 0 | H16: 0 | I16: 0 | J16: 2 | K16: =J16 -> 2 | L16: =K16 -> 2 | M16: 1.5 | N16: =M16 -> 1.5 | O16: =N16 -> 1.5 | P16: 2 | Q16: =P16 -> 2 | R16: 3 | S16: =R16 -> 3 | T16: 4 | U16: =T16 -> 4 | V16: =U16 -> 4 | W16: =V16 -> 4 | X16: =W16 -> 4 | Y16: =X16 -> 4 | Z16: =Y16 -> 4 | AA16: =Z16 -> 4
C17: Dev Ops | D17: 0 | E17: =D17 -> 0 | F17: =E17 -> 0 | G17: =F17 -> 0 | H17: =G17 -> 0 | I17: =H17 -> 0 | J17: =I17 -> 0 | K17: =J17 -> 0 | L17: =K17 -> 0 | ... Q17: =P17 -> 0 | R17: 37500 | S17: =R17 -> 37500 | T17: =S17*(1+$D$4) -> 38812.5 | U17: =T17 -> 38812.5 | V17: =U17 -> 38812.5 | W17: =V17 -> 38812.5 | X17: =W17 -> 38812.5 | Y17: =X17 -> 38812.5 | Z17: =Y17 -> 38812.5 | AA17: =Z17 -> 38812.5
C18: Director - Product | D18: 0 | E18: =D18 -> 0 | F18: =E18 -> 0 | G18: =F18 -> 0 | H18: =G18 -> 0 | I18: =H18 -> 0 | J18: =I18 -> 0 | K18: =J18 -> 0 | L18: =K18 -> 0 | ... AA18: =Z18 -> 0
C19: Product Manager | D19: 0 | E19: =D19 -> 0 | F19: =E19 -> 0 | G19: =F19 -> 0 | H19: =G19 -> 0 | I19: =H19 -> 0 | J19: =I19 -> 0 | K19: =J19 -> 0 | L19: =K19 -> 0 | ... AA19: =Z19 -> 0
C20: Project Manager | D20: 0 | E20: =D20 -> 0 | F20: =E20 -> 0 | G20: =F20 -> 0 | H20: =G20 -> 0 | I20: =H20 -> 0 | J20: =I20 -> 0 | K20: =J20 -> 0 | L20: =K20 -> 0 | ... AA20: =Z20 -> 0
C21: IT Engineer | D21: 0 | E21: =D21 -> 0 | F21: =E21 -> 0 | G21: =F21 -> 0 | H21: =G21 -> 0 | I21: =H21 -> 0 | J21: =I21 -> 0 | K21: =J21 -> 0 | L21: =K21 -> 0 | ... AA21: =Z21 -> 0
C22: UI Designer | D22: 0 | E22: =D22 -> 0 | F22: =E22 -> 0 | G22: =F22 -> 0 | H22: =G22 -> 0 | I22: =H22 -> 0 | J22: =I22 -> 0 | K22: =J22 -> 0 | L22: =K22 -> 0 | ... AA22: =Z22 -> 0
C23: UX Designer | D23: 0 | E23: =D23 -> 0 | F23: =E23 -> 0 | G23: =F23 -> 0 | H23: =G23 -> 0 | I23: =H23 -> 0 | J23: =I23 -> 0 | K23: =J23 -> 0 | L23: =K23 -> 0 | ... Q23: =P23 -> 0 | R23: 33000 | S23: =R23 -> 33000 | T23: =R23*(1+$D$4) -> 34155 | U23: =T23 -> 34155 | V23: =U23 -> 34155 | W23: =V23 -> 34155 | X23: =W23 -> 34155 | Y23: =X23 -> 34155 | Z23: =Y23 -> 34155 | AA23: =Z23 -> 34155
C24: Data Analyst | D24: 0 | E24: =D24 -> 0 | F24: =E24 -> 0 | G24: =F24 -> 0 | H24: =G24 -> 0 | I24: =H24 -> 0 | J24: =I24 -> 0 | K24: =J24 -> 0 | L24: =K24 -> 0 | ... AA24: =Z24 -> 0
C25: Data Scientist | D25: 0 | E25: 0 | F25: 0 | G25: 0 | H25: 0 | I25: 0 | J25: 0 | K25: 0 | L25: 0 | M25: =L25 -> 0 | N25: 0 | O25: =N25 -> 0 | P25: =O25 -> 0 | Q25: =P25 -> 0 | R25: =Q25 -> 0 | S25: =R25 -> 0 | T25: =S25 -> 0 | U25: =T25 -> 0 | V25: =U25 -> 0 | ... AA25: =Z25 -> 0
C26: Marketing
C27: VP Marketing | D27: 0 | E27: 0 | F27: 0 | G27: 0 | H27: 0 | I27: 0 | J27: =I27 -> 0 | K27: =J27 -> 0 | L27: =K27*(1+$D$4) -> 0 | M27: 0 | N27: =M27 -> 0 | O27: =N27 -> 0 | P27: =O27 -> 0 | Q27: =P27 -> 0 | R27: =Q27 -> 0 | S27: 45000 | T27: =S27*(1+$D$4) -> 46575 | U27: =T27 -> 46575 | V27: =U27 -> 46575 | W27: =V27 -> 46575 | X27: =W27 -> 46575 | Y27: =X27 -> 46575 | Z27: =Y27 -> 46575 | AA27: =Z27 -> 46575
C28: Sr. Manager Marketing | D28: 0 | E28: 0 | F28: =E28 -> 0 | G28: =F28 -> 0 | H28: 0 | I28: 0 | J28: 25000 | K28: 25000 | L28: 25000 | M28: =L28 -> 25000 | N28: =M28 -> 25000 | O28: =N28 -> 25000 | P28: =O28*(1+$D$4) -> 25875 | Q28: =P28 -> 25875 | R28: =Q28 -> 25875 | S28: =R28 -> 25875 | T28: =P28*(1+$D$4) -> 26780.625 | U28: =T28 -> 26780.625 | V28: =U28 -> 26780.625 | W28: =V28 -> 26780.625 | X28: =W28 -> 26780.625 | Y28: =X28 -> 26780.625 | Z28: =Y28 -> 26780.625 | AA28: =Z28 -> 26780.625
C29: Copywriter | D29: 0 | E29: 0 | F29: 0 | G29: 0 | H29: 0 | I29: 0 | J29: =I29 -> 0 | K29: =J29 -> 0 | L29: =K29 -> 0 | M29: =L29 -> 0 | N29: =M29 -> 0 | O29: =N29 -> 0 | P29: =O29*(1+$D$4) -> 0 | Q29: =P29 -> 0 | R29: =Q29 -> 0 | S29: =R29 -> 0 | T29: =P29*(1+$D$4) -> 0 | U29: =T29 -> 0 | V29: =U29 -> 0 | W29: =V29 -> 0 | X29: =W29 -> 0 | Y29: =X29 -> 0 | Z29: =Y29 -> 0 | AA29: =Z29 -> 0
C30: Designer | D30: 0 | E30: 0 | F30: 0 | G30: 0 | H30: 0 | I30: 0 | J30: 0 | K30: 0 | L30: 0 | M30: =L30 -> 0 | N30: 0 | O30: =N30 -> 0 | P30: =O30*(1+$D$4) -> 0 | Q30: =P30 -> 0 | R30: 0 | S30: =R30 -> 0 | T30: =S30*(1+$D$4) -> 0 | U30: =T30 -> 0 | V30: 0 | W30: =V30 -> 0 | X30: =W30 -> 0 | Y30: =X30 -> 0 | Z30: =Y30 -> 0 | AA30: =Z30 -> 0
C31: Search | D31: 0 | E31: 0 | F31: =E31 -> 0 | G31: =F31 -> 0 | H31: 0 | I31: 0 | J31: =I31 -> 0 | K31: =J31 -> 0 | L31: 0 | M31: =L31 -> 0 | N31: =M31 -> 0 | O31: =N31 -> 0 | P31: =O31*(1+$D$4) -> 0 | Q31: =P31 -> 0 | R31: =Q31 -> 0 | S31: =R31 -> 0 | T31: =S31*(1+$D$4) -> 0 | U31: =T31 -> 0 | V31: =U31 -> 0 | W31: =V31 -> 0 | X31: =W31 -> 0 | Y31: =X31 -> 0 | Z31: =Y31 -> 0 | AA31: =Z31 -> 0
C32: Display/Partnerships | D32: 0 | E32: 0 | F32: 0 | G32: 0 | H32: 0 | I32: 0 | J32: 0 | K32: 0 | L32: 0 | M32: =L32 -> 0 | N32: =M32 -> 0 | O32: =N32 -> 0 | P32: =O32*(1+$D$4) -> 0 | Q32: =P32 -> 0 | R32: =Q32 -> 0 | S32: =R32 -> 0 | T32: =S32*(1+$D$4) -> 0 | U32: =T32 -> 0 | V32: =U32 -> 0 | W32: =V32 -> 0 | X32: =W32 -> 0 | Y32: =X32 -> 0 | Z32: =Y32 -> 0 | AA32: =Z32 -> 0
C33: Email/SMS | D33: 0 | E33: 0 | F33: 0 | G33: 0 | H33: 0 | I33: 0 | J33: 0 | K33: =J33 -> 0 | L33: =K33*(1+$D$4) -> 0 | M33: =L33 -> 0 | N33: =M33 -> 0 | O33: =N33 -> 0 | P33: =O33*(1+$D$4) -> 0 | Q33: =P33 -> 0 | R33: =Q33 -> 0 | S33: =R33 -> 0 | T33: =S33*(1+$D$4) -> 0 | U33: =T33 -> 0 | V33: =U33 -> 0 | W33: =V33 -> 0 | X33: =W33 -> 0 | Y33: =X33 -> 0 | Z33: =Y33 -> 0 | AA33: =Z33 -> 0
C34: Director - Business Development | D34: 0 | E34: 0 | F34: 0 | G34: 0 | H34: 0 | I34: 0 | J34: =I34 -> 0 | K34: =J34 -> 0 | L34: =K34*(1+$D$4) -> 0 | M34: =L34 -> 0 | N34: =M34 -> 0 | O34: 0 | P34: =O34*(1+$D$4) -> 0 | Q34: =P34 -> 0 | R34: =Q34 -> 0 | S34: =R34 -> 0 | T34: =S34 -> 0 | U34: =T34 -> 0 | V34: 50000 | W34: =V34 -> 50000 | X34: =W34 -> 50000 | Y34: =X34 -> 50000 | Z34: =Y34 -> 50000 | AA34: =Z34 -> 50000
C35: Business Development | D35: 0 | E35: 0 | F35: 0 | G35: 0 | H35: 0 | I35: 0 | J35: =I35 -> 0 | K35: =J35 -> 0 | L35: 0 | M35: =L35 -> 0 | N35: 0 | O35: 0 | P35: 0 | Q35: =P35 -> 0 | R35: 30000 | S35: =R35 -> 30000 | T35: =S35*(1+$D$4) -> 31050 | U35: =T35 -> 31050 | V35: =U35 -> 31050 | W35: =V35 -> 31050 | X35: =W35 -> 31050 | Y35: =X35 -> 31050 | Z35: =Y35 -> 31050 | AA35: =Z35 -> 31050
C36: Business Development Hires | D36: 0 | E36: =D36 -> 0 | F36: 0 | G36: 0 | H36: =G36 -> 0 | I36: =H36 -> 0 | J36: =I36 -> 0 | K36: =J36 -> 0 | L36: 0 | M36: 0 | N36: =M36 -> 0 | O36: =N36 -> 0 | P36: =O36 -> 0 | Q36: =P36 -> 0 | R36: 1 | S36: =R36 -> 1 | T36: =S36*(1+$D$4) -> 1.035 | U36: =T36 -> 1.035 | V36: =U36 -> 1.035 | W36: =V36 -> 1.035 | X36: =W36 -> 1.035 | Y36: =X36 -> 1.035 | Z36: =Y36 -> 1.035 | AA36: =Z36 -> 1.035
C37: Customer Service | D37: 0 | E37: 0 | F37: 0 | G37: 0 | H37: 0 | I37: 0 | J37: =I37 -> 0 | K37: =J37 -> 0 | L37: =K37*(1+$D$4) -> 0 | M37: =L37 -> 0 | N37: =M37 -> 0 | O37: =N37 -> 0 | P37: 8000 | Q37: =P37 -> 8000 | R37: =Q37 -> 8000 | S37: =R37 -> 8000 | T37: =P37*(1+$D$4) -> 8280 | U37: =T37 -> 8280 | V37: =U37 -> 8280 | W37: =V37 -> 8280 | X37: =W37 -> 8280 | Y37: =X37 -> 8280 | Z37: =Y37 -> 8280 | AA37: =Z37 -> 8280
C38: Editorial | H38: 0 | I38: 0 | J38: =I38 -> 0 | K38: =J38 -> 0 | L38: =K38*(1+$D$4) -> 0 | M38: =L38 -> 0 | N38: 0 | O38: =N38 -> 0 | P38: =O38*(1+$D$4) -> 0 | Q38: =P38 -> 0 | R38: =Q38 -> 0 | S38: =R38 -> 0 | T38: =S38*(1+$D$4) -> 0 | U38: =T38 -> 0 | V38: =U38 -> 0 | W38: =V38 -> 0 | X38: =W38 -> 0 | Y38: =X38 -> 0 | Z38: =Y38 -> 0 | AA38: =Z38 -> 0
C39: Fashion Editor | D39: 0 | E39: 0 | F39: 0 | G39: 0 | H39: 0 | I39: =H39 -> 0 | J39: 0 | K39: =J39 -> 0 | L39: =K39*(1+$D$4) -> 0 | M39: =L39 -> 0 | N39: =M39 -> 0 | O39: =N39 -> 0 | P39: =O39*(1+$D$4) -> 0 | Q39: =P39 -> 0 | R39: =Q39 -> 0 | S39: =R39 -> 0 | T39: =S39*(1+$D$4) -> 0 | U39: =T39 -> 0 | V39: 35000 | W39: =V39 -> 35000 | X39: =W39 -> 35000 | Y39: =X39 -> 35000 | Z39: =Y39 -> 35000 | AA39: =Z39 -> 35000
C40: Fashion Associate | D40: 0 | E40: 0 | F40: 0 | G40: 0 | H40: 0 | I40: =H40 -> 0 | J40: 0 | K40: =J40 -> 0 | L40: =K40*(1+$D$4) -> 0 | M40: =L40 -> 0 | N40: =M40 -> 0 | O40: =N40 -> 0 | P40: =O40 -> 0 | Q40: =P40 -> 0 | R40: =Q40 -> 0 | S40: =R40 -> 0 | T40: 11500 | U40: =T40 -> 11500 | V40: =U40 -> 11500 | W40: =V40 -> 11500 | X40: =W40 -> 11500 | Y40: =X40 -> 11500 | Z40: =Y40 -> 11500 | AA40: =Z40 -> 11500
C41: HR / Recruitment
C42: HR Manager | D42: 0 | E42: 0 | F42: 0 | G42: 0 | H42: 0 | I42: 0 | J42: =I42 -> 0 | K42: =J42 -> 0 | L42: 0 | M42: =L42 -> 0 | N42: =M42 -> 0 | O42: =N42 -> 0 | P42: =O42*(1+$D$4) -> 0 | Q42: =P42 -> 0 | R42: =Q42 -> 0 | S42: =R42 -> 0 | T42: =S42*(1+$D$4) -> 0 | U42: =T42 -> 0 | V42: 35000 | W42: =V42 -> 35000 | X42: =W42 -> 35000 | Y42: =X42 -> 35000 | Z42: =Y42 -> 35000 | AA42: =Z42 -> 35000
C43: Recruiter | D43: 0 | E43: 0 | F43: 0 | G43: 0 | H43: 0 | I43: =H43 -> 0 | J43: =I43 -> 0 | K43: =J43 -> 0 | L43: 0 | M43: =L43 -> 0 | N43: =M43 -> 0 | O43: =N43 -> 0 | P43: =O43 -> 0 | Q43: =P43 -> 0 | R43: =Q43 -> 0 | S43: =R43 -> 0 | T43: 35000 | U43: =T43 -> 35000 | V43: =U43 -> 35000 | W43: =V43 -> 35000 | X43: =W43 -> 35000 | Y43: =X43 -> 35000 | Z43: =Y43 -> 35000 | AA43: =Z43 -> 35000
...

Sheet P&L
B2: Income Statement (in US$) | E2: Q1-17 | F2: Q2-17 | G2: Q3-17 | H2: Q4-17 | I2: 2017 | J2: Q1-18 | K2: Q2-18 | L2: Q3-18 | M2: Q4-18 | N2: 2018 | O2: Q1-19 | P2: Q2-19 | Q2: Q3-19 | R2: Q4-19 | S2: 2019 | T2: Q1-20 | U2: Q2-20 | V2: Q3-20 | W2: Q4-20 | X2: 2020 | Y2: Q1-21 | Z2: Q2-21 | AA2: Q3-21 | AB2: Q4-21 | AC2: 2021 | AD2: Q1-22 | AE2: Q2-22 | AF2: Q3-22 | AG2: Q4-22 | AH2: 2022
B3: Revenues | E3: =E4 -> 0 | F3: =F4 -> 0 | G3: =G4 -> 0 | H3: =H4 -> 0 | I3: =I4 -> 0 | J3: =J4 -> 0 | K3: =K4 -> 0 | L3: =L4 -> 0 | ... AH3: =AH4 -> 57483213
C4: Affiliate Marketing | E4: =SUM(E5:E6) -> 0 | F4: =SUM(F5:F6) -> 0 | G4: =SUM(G5:G6) -> 0 | H4: =SUM(H5:H6) -> 0 | I4: =SUM(E4:H4) -> 0 | J4: =SUM(J5:J6) -> 0 | K4: =SUM(K5:K6) -> 0 | L4: =SUM(L5:L6) -> 0 | M4: =SUM(M5:M6) -> 0 | N4: =SUM(J4:M4) -> 0 | O4: =SUM(O5:O6) -> 128907.18 | P4: =SUM(P5:P6) -> 234368.49 | Q4: =SUM(Q5:Q6) -> 366934.51 | R4: =SUM(R5:R6) -> 535504.02 | S4: =SUM(O4:R4) -> 1265714.2 | T4: =SUM(T5:T6) -> 779491.03 | U4: =SUM(U5:U6) -> 1149722.6 | V4: =SUM(V5:V6) -> 1722697.7 | W4: =SUM(W5:W6) -> 2391918.1 | X4: =SUM(T4:W4) -> 6043829.4 | Y4: =SUM(Y5:Y6) -> 3646864.4 | Z4: =SUM(Z5:Z6) -> 4740916.7 | AA4: =SUM(AA5:AA6) -> 6163197.6 | AB4: =SUM(AB5:AB6) -> 8012157.3 | AC4: =SUM(Y4:AB4) -> 22563136 | AD4: =SUM(AD5:AD6) -> 10523180 | AE4: =SUM(AE5:AE6) -> 12756675 | AF4: =SUM(AF5:AF6) -> 15462636 | AG4: =SUM(AG5:AG6) -> 18740722 | AH4: =SUM(AD4:AG4) -> 57483213
D5: Women | E5: ='Assumptions & Sensitivity'!E21 -> 0 | F5: ='Assumptions & Sensitivity'!F21 -> 0 | G5: ='Assumptions & Sensitivity'!G21 -> 0 | H5: ='Assumptions & Sensitivity'!H21 -> 0 | I5: =SUM(E5:H5) -> 0 | J5: ='Assumptions & Sensitivity'!I21 -> 0 | K5: ='Assumptions & Sensitivity'!J21 -> 0 | L5: ='Assumptions & Sensitivity'!K21 -> 0 | M5: ='Assumptions & Sensitivity'!L21 -> 0 | N5: =SUM(J5:M5) -> 0 | O5: ='Assumptions & Sensitivity'!M21 -> 111214.38 | P5: ='Assumptions & Sensitivity'!N21 -> 202198.44 | Q5: ='Assumptions & Sensitivity'!O21 -> 316567.26 | R5: ='Assumptions & Sensitivity'!P21 -> 461997.42 | S5: =SUM(O5:R5) -> 1091977.5 | T5: ='Assumptions & Sensitivity'!Q21 -> 672495.18 | U5: ='Assumptions & Sensitivity'!R21 -> 991908.42 | V5: ='Assumptions & Sensitivity'!S21 -> 1486235.9 | W5: ='Assumptions & Sensitivity'!T21 -> 2063597.4 | X5: =SUM(T5:W5) -> 5214236.9 | Y5: ='Assumptions & Sensitivity'!U21 -> 3146286.2 | Z5: ='Assumptions & Sensitivity'!V21 -> 4090168 | AA5: ='Assumptions & Sensitivity'!W21 -> 5317221.8 | AB5: ='Assumptions & Sensitivity'!X21 -> 6912390.7 | AC5: =SUM(Y5:AB5) -> 19466067 | AD5: ='Assumptions & Sensitivity'!Y21 -> 9078743.5 | AE5: ='Assumptions & Sensitivity'!Z21 -> 11005662 | AF5: ='Assumptions & Sensitivity'!AA21 -> 13340196 | AG5: ='Assumptions & Sensitivity'!AB21 -> 16168322 | AH5: =SUM(AD5:AG5) -> 49592924
D6: Men | E6: ='Assumptions & Sensitivity'!E38 -> 0 | F6: ='Assumptions & Sensitivity'!F38 -> 0 | G6: ='Assumptions & Sensitivity'!G38 -> 0 | H6: ='Assumptions & Sensitivity'!H38 -> 0 | I6: =SUM(E6:H6) -> 0 | J6: ='Assumptions & Sensitivity'!I38 -> 0 | K6: ='Assumptions & Sensitivity'!J38 -> 0 | L6: ='Assumptions & Sensitivity'!K38 -> 0 | M6: ='Assumptions & Sensitivity'!L38 -> 0 | N6: =SUM(J6:M6) -> 0 | O6: ='Assumptions & Sensitivity'!M38 -> 17692.8 | P6: ='Assumptions & Sensitivity'!N38 -> 32170.05 | Q6: ='Assumptions & Sensitivity'!O38 -> 50367.25 | R6: ='Assumptions & Sensitivity'!P38 -> 73506.6 | S6: =SUM(O6:R6) -> 173736.7 | T6: ='Assumptions & Sensitivity'!Q38 -> 106995.85 | U6: ='Assumptions & Sensitivity'!R38 -> 157814.15 | V6: ='Assumptions & Sensitivity'!S38 -> 236461.75 | W6: ='Assumptions & Sensitivity'!T38 -> 328320.75 | X6: =SUM(T6:W6) -> 829592.5 | Y6: ='Assumptions & Sensitivity'!U38 -> 500578.2 | Z6: ='Assumptions & Sensitivity'!V38 -> 650748.75 | AA6: ='Assumptions & Sensitivity'!W38 -> 845975.8 | AB6: ='Assumptions & Sensitivity'!X38 -> 1099766.6 | AC6: =SUM(Y6:AB6) -> 3097069.4 | AD6: ='Assumptions & Sensitivity'!Y38 -> 1444436.7 | AE6: ='Assumptions & Sensitivity'!Z38 -> 1751013 | AF6: ='Assumptions & Sensitivity'!AA38 -> 2122440 | AG6: ='Assumptions & Sensitivity'!AB38 -> 2572399.3 | AH6: =SUM(AD6:AG6) -> 7890289
B7: Gross Profits | E7: =E3 -> 0 | F7: =F3 -> 0 | G7: =G3 -> 0 | H7: =H3 -> 0 | I7: =SUM(E7:H7) -> 0 | J7: =J3 -> 0 | K7: =K3 -> 0 | L7: =L3 -> 0 | M7: =M3 -> 0 | N7: =SUM(J7:M7) -> 0 | O7: =O3 -> 128907.18 | P7: =P3 -> 234368.49 | Q7: =Q3 -> 366934.51 | R7: =R3 -> 535504.02 | S7: =SUM(O7:R7) -> 1265714.2 | T7: =T3 -> 779491.03 | U7: =U3 -> 1149722.6 | V7: =V3 -> 1722697.7 | W7: =W3 -> 2391918.1 | X7: =SUM(T7:W7) -> 6043829.4 | Y7: =Y3 -> 3646864.4 | Z7: =Z3 -> 4740916.7 | AA7: =AA3 -> 6163197.6 | AB7: =AB3 -> 8012157.3 | AC7: =SUM(Y7:AB7) -> 22563136 | AD7: =AD3 -> 10523180 | AE7: =AE3 -> 12756675 | AF7: =AF3 -> 15462636 | AG7: =AG3 -> 18740722 | AH7: =SUM(AD7:AG7) -> 57483213
C8: Less: Operating Costs | E8: ='Assumptions & Sensitivity'!E77 -> 30169.56 | F8: ='Assumptions & Sensitivity'!F77 -> 54637.7 | G8: ='Assumptions & Sensitivity'!G77 -> 48699.1 | H8: ='Assumptions & Sensitivity'!H77 -> 60067.14 | I8: =SUM(E8:H8) -> 193573.5 | J8: ='Assumptions & Sensitivity'!I77 -> 69000 | K8: ='Assumptions & Sensitivity'!J77 -> 69000 | L8: ='Assumptions & Sensitivity'!K77 -> 454266.56 | M8: ='Assumptions & Sensitivity'!L77 -> 502766.56 | N8: =SUM(J8:M8) -> 1095033.1 | O8: ='Assumptions & Sensitivity'!M77 -> 519485.99 | P8: ='Assumptions & Sensitivity'!N77 -> 517350.05 | Q8: ='Assumptions & Sensitivity'!O77 -> 566066.62 | R8: ='Assumptions & Sensitivity'!P77 -> 589179.57 | S8: =SUM(O8:R8) -> 2192082.2 | T8: ='Assumptions & Sensitivity'!Q77 -> 803425.06 | U8: ='Assumptions & Sensitivity'!R77 -> 1060751.9 | V8: ='Assumptions & Sensitivity'!S77 -> 1413074.6 | W8: ='Assumptions & Sensitivity'!T77 -> 1749229.9 | X8: =SUM(T8:W8) -> 5026481.5 | Y8: ='Assumptions & Sensitivity'!U77 -> 2354164.4 | Z8: ='Assumptions & Sensitivity'!V77 -> 2796618.3 | AA8: ='Assumptions & Sensitivity'!W77 -> 3493826.4 | AB8: ='Assumptions & Sensitivity'!X77 -> 4238131.9 | AC8: =SUM(Y8:AB8) -> 12882741 | AD8: ='Assumptions & Sensitivity'!Y77 -> 5303088 | AE8: ='Assumptions & Sensitivity'!Z77 -> 6087661.8 | AF8: ='Assumptions & Sensitivity'!AA77 -> 7181033.3 | AG8: ='Assumptions & Sensitivity'!AB77 -> 8341588.4 | AH8: =SUM(AD8:AG8) -> 26913371
B9: Profit (Losses) Before Taxes (PBT) | E9: =E7-E8 -> -30169.56 | F9: =F7-F8 -> -54637.7 | G9: =G7-G8 -> -48699.1 | H9: =H7-H8 -> -60067.14 | I9: =SUM(E9:H9) -> -193573.5 | J9: =J7-J8 -> -69000 | K9: =K7-K8 -> -69000 | L9: =L7-L8 -> -454266.56 | M9: =M7-M8 -> -502766.56 | N9: =SUM(J9:M9) -> -1095033.1 | O9: =O7-O8 -> -390578.81 | P9: =P7-P8 -> -282981.56 | Q9: =Q7-Q8 -> -199132.11 | R9: =R7-R8 -> -53675.548 | S9: =SUM(O9:R9) -> -926368.04 | T9: =T7-T8 -> -23934.033 | U9: =U7-U8 -> 88970.657 | V9: =V7-V8 -> 309623.05 | W9: =W7-W8 -> 642688.27 | X9: =SUM(T9:W9) -> 1017347.9 | Y9: =Y7-Y8 -> 1292700 | Z9: =Z7-Z8 -> 1944298.4 | AA9: =AA7-AA8 -> 2669371.3 | AB9: =AB7-AB8 -> 3774025.4 | AC9: =SUM(Y9:AB9) -> 9680395 | AD9: =AD7-AD8 -> 5220092.2 | AE9: =AE7-AE8 -> 6669012.9 | AF9: =AF7-AF8 -> 8281602.7 | AG9: =AG7-AG8 -> 10399133 | AH9: =SUM(AD9:AG9) -> 30569841
C10: Cumulative PBT | E10: =SUM($E$9:E9) -> -30169.56 | F10: =SUM($E$9:F9) -> -84807.26 | G10: =SUM($E$9:G9) -> -133506.36 | H10: =SUM($E$9:H9) -> -193573.5 | I10: =H10 -> -193573.5 | J10: =I10+J9 -> -262573.5 | K10: =J10+K9 -> -331573.5 | L10: =K10+L9 -> -785840.06 | M10: =L10+M9 -> -1288606.6 | N10: =M10 -> -1288606.6 | O10: =N10+O9 -> -1679185.4 | P10: =O10+P9 -> -1962167 | Q10: =P10+Q9 -> -2161299.1 | R10: =Q10+R9 -> -2214974.7 | S10: =R10 -> -2214974.7 | T10: =S10+T9 -> -2238908.7 | U10: =T10+U9 -> -2149938 | V10: =U10+V9 -> -1840315 | W10: =V10+W9 -> -1197626.7 | X10: =W10 -> -1197626.7 | Y10: =X10+Y9 -> 95073.242 | Z10: =Y10+Z9 -> 2039371.6 | AA10: =Z10+AA9 -> 4708742.9 | AB10: =AA10+AB9 -> 8482768.3 | AC10: =AB10 -> 8482768.3 | AD10: =AB10+AD9 -> 13702861 | AE10: =AD10+AE9 -> 20371873 | AF10: =AE10+AF9 -> 28653476 | AG10: =AF10+AG9 -> 39052609 | AH10: =AG10 -> 39052609
C11: Less: Taxes | E11: =IF(E9<=0,0,IF(E10<=0,0,(MIN(E9,E10)*'Assumptions & Sensitivity'!$D$94))) -> 0 | F11: =IF(F9<=0,0,IF(F10<=0,0,(MIN(F9,F10)*'Assumptions & Sensitivity'!$D$94))) -> 0 | G11: =IF(G9<=0,0,IF(G10<=0,0,(MIN(G9,G10)*'Assumptions & Sensitivity'!$D$94))) -> 0 | H11: =IF(H9<=0,0,IF(H10<=0,0,(MIN(H9,H10)*'Assumptions & Sensitivity'!$D$94))) -> 0 | I11: =SUM(E11:H11) -> 0 | J11: =IF(J9<=0,0,IF(J10<=0,0,(MIN(J9,J10)*'Assumptions & Sensitivity'!$D$94))) -> 0 | K11: =IF(K9<=0,0,IF(K10<=0,0,(MIN(K9,K10)*'Assumptions & Sensitivity'!$D$94))) -> 0 | L11: =IF(L9<=0,0,IF(L10<=0,0,(MIN(L9,L10)*'Assumptions & Sensitivity'!$D$94))) -> 0 | M11: =IF(M9<=0,0,IF(M10<=0,0,(MIN(M9,M10)*'Assumptions & Sensitivity'!$D$94))) -> 0 | N11: =SUM(J11:M11) -> 0 | O11: =IF(O9<=0,0,IF(O10<=0,0,(MIN(O9,O10)*'Assumptions & Sensitivity'!$D$94))) -> 0 | P11: =IF(P9<=0,0,IF(P10<=0,0,(MIN(P9,P10)*'Assumptions & Sensitivity'!$D$94))) -> 0 | Q11: =IF(Q9<=0,0,IF(Q10<=0,0,(MIN(Q9,Q10)*'Assumptions & Sensitivity'!$D$94))) -> 0 | R11: =IF(R9<=0,0,IF(R10<=0,0,(MIN(R9,R10)*'Assumptions & Sensitivity'!$D$94))) -> 0 | S11: =SUM(O11:R11) -> 0 | T11: =IF(T9<=0,0,IF(T10<=0,0,(MIN(T9,T10)*'Assumptions & Sensitivity'!$D$94))) -> 0 | U11: =IF(U9<=0,0,IF(U10<=0,0,(MIN(U9,U10)*'Assumptions & Sensitivity'!$D$94))) -> 0 | V11: =IF(V9<=0,0,IF(V10<=0,0,(MIN(V9,V10)*'Assumptions & Sensitivity'!$D$94))) -> 0 | W11: =IF(W9<=0,0,IF(W10<=0,0,(MIN(W9,W10)*'Assumptions & Sensitivity'!$D$94))) -> 0 | X11: =SUM(T11:W11) -> 0 | Y11: =IF(Y9<=0,0,IF(Y10<=0,0,(MIN(Y9,Y10)*'Assumptions & Sensitivity'!$D$94))) -> 19965.381 | Z11: =IF(Z9<=0,0,IF(Z10<=0,0,(MIN(Z9,Z10)*'Assumptions & Sensitivity'!$D$94))) -> 408302.66 | AA11: =IF(AA9<=0,0,IF(AA10<=0,0,(MIN(AA9,AA10)*'Assumptions & Sensitivity'!$D$94))) -> 560567.96 | AB11: =IF(AB9<=0,0,IF(AB10<=0,0,(MIN(AB9,AB10)*'Assumptions & Sensitivity'!$D$94))) -> 792545.33 | AC11: =SUM(Y11:AB11) -> 1781381.3 | AD11: =IF(AD9<=0,0,IF(AD10<=0,0,(MIN(AD9,AD10)*'Assumptions & Sensitivity'!$D$94))) -> 1096219.4 | AE11: =IF(AE9<=0,0,IF(AE10<=0,0,(MIN(AE9,AE10)*'Assumptions & Sensitivity'!$D$94))) -> 1400492.7 | AF11: =IF(AF9<=0,0,IF(AF10<=0,0,(MIN(AF9,AF10)*'Assumptions & Sensitivity'!$D$94))) -> 1739136.6 | AG11: =IF(AG9<=0,0,IF(AG10<=0,0,(MIN(AG9,AG10)*'Assumptions & Sensitivity'!$D$94))) -> 2183818 | AH11: =SUM(AD11:AG11) -> 6419666.7
B12: Net Profit | E12: =E9-E11 -> -30169.56 | F12: =F9-F11 -> -54637.7 | G12: =G9-G11 -> -48699.1 | H12: =H9-H11 -> -60067.14 | I12: =I9-I11 -> -193573.5 | J12: =J9-J11 -> -69000 | K12: =K9-K11 -> -69000 | L12: =L9-L11 -> -454266.56 | ... AH12: =AH9-AH11 -> 24150175

Sheet BS
B2: Balance Sheet | E2: 2016 | F2: Q1-17 | G2: Q2-17 | H2: Q3-17 | I2: Q4-17 | J2: 2017 | K2: Q1-18 | L2: Q2-18 | M2: Q3-18 | N2: Q4-18 | O2: 2018 | P2: Q1-19 | Q2: Q2-19 | R2: Q3-19 | S2: Q4-19 | T2: 2019 | U2: Q1-20 | V2: Q2-20 | W2: Q3-20 | X2: Q4-20 | Y2: 2020 | Z2: Q1-21 | AA2: Q2-21 | AB2: Q3-21 | AC2: Q4-21 | AD2: 2021 | AE2: Q1-22 | AF2: Q2-22 | AG2: Q3-22 | AH2: Q4-22 | AI2: 2022
B3: Current Liabilities & Provisions | E3: =SUM(E4:E4) -> 0 | F3: =SUM(F4:F4) -> 0 | G3: =SUM(G4:G4) -> 0 | H3: =SUM(H4:H4) -> 0 | I3: =SUM(I4:I4) -> 0 | J3: =I3 -> 0 | K3: =SUM(K4:K4) -> 15923.077 | L3: =SUM(L4:L4) -> 15923.077 | M3: =SUM(M4:M4) -> 104830.75 | N3: =SUM(N4:N4) -> 116023.05 | O3: =N3 -> 116023.05 | P3: =SUM(P4:P4) -> 119881.38 | Q3: =SUM(Q4:Q4) -> 119388.47 | R3: =SUM(R4:R4) -> 130630.76 | S3: =SUM(S4:S4) -> 135964.52 | T3: =S3 -> 135964.52 | U3: =SUM(U4:U4) -> 185405.78 | V3: =SUM(V4:V4) -> 244788.9 | W3: =SUM(W4:W4) -> 326094.15 | X3: =SUM(X4:X4) -> 403668.43 | Y3: =X3 -> 403668.43 | Z3: =SUM(Z4:Z4) -> 543268.71 | AA3: =SUM(AA4:AA4) -> 645373.46 | AB3: =SUM(AB4:AB4) -> 806267.63 | AC3: =SUM(AC4:AC4) -> 978030.44 | AD3: =AC3 -> 978030.44 | AE3: =SUM(AE4:AE4) -> 2972940.2 | AF3: =SUM(AF4:AF4) -> 1223789.5 | AG3: =SUM(AG4:AG4) -> 1404845 | AH3: =SUM(AH4:AH4) -> 1657161.5 | AI3: =AH3 -> 1657161.5
C4: [+] Accounts payable | F4: 0 | G4: 0 | H4: 0 | I4: 0 | J4: =I4 -> 0 | K4: =('Assumptions & Sensitivity'!$D$84/91)*'P&L'!J8 -> 15923.077 | L4: =('Assumptions & Sensitivity'!$D$84/91)*'P&L'!K8 -> 15923.077 | M4: =('Assumptions & Sensitivity'!$D$84/91)*'P&L'!L8 -> 104830.75 | N4: =('Assumptions & Sensitivity'!$D$84/91)*'P&L'!M8 -> 116023.05 | O4: =N4 -> 116023.05 | P4: =('Assumptions & Sensitivity'!$D$84/91)*'P&L'!O8 -> 119881.38 | Q4: =('Assumptions & Sensitivity'!$D$84/91)*'P&L'!P8 -> 119388.47 | R4: =('Assumptions & Sensitivity'!$D$84/91)*'P&L'!Q8 -> 130630.76 | S4: =('Assumptions & Sensitivity'!$D$84/91)*'P&L'!R8 -> 135964.52 | T4: =S4 -> 135964.52 | U4: =('Assumptions & Sensitivity'!$D$84/91)*'P&L'!T8 -> 185405.78 | V4: =('Assumptions & Sensitivity'!$D$84/91)*'P&L'!U8 -> 244788.9 | W4: =('Assumptions & Sensitivity'!$D$84/91)*'P&L'!V8 -> 326094.15 | X4: =('Assumptions & Sensitivity'!$D$84/91)*'P&L'!W8 -> 403668.43 | Y4: =X4 -> 403668.43 | Z4: =('Assumptions & Sensitivity'!$D$84/91)*'P&L'!Y8 -> 543268.71 | AA4: =('Assumptions & Sensitivity'!$D$84/91)*'P&L'!Z8 -> 645373.46 | AB4: =('Assumptions & Sensitivity'!$D$84/91)*'P&L'!AA8 -> 806267.63 | AC4: =('Assumptions & Sensitivity'!$D$84/91)*'P&L'!AB8 -> 978030.44 | AD4: =AC4 -> 978030.44 | AE4: =('Assumptions & Sensitivity'!$D$84/91)*'P&L'!AC8 -> 2972940.2 | AF4: =('Assumptions & Sensitivity'!$D$84/91)*'P&L'!AD8 -> 1223789.5 | AG4: =('Assumptions & Sensitivity'!$D$84/91)*'P&L'!AE8 -> 1404845 | AH4: =('Assumptions & Sensitivity'!$D$84/91)*'P&L'!AF8 -> 1657161.5 | AI4: =AH4 -> 1657161.5
B5: Shareholders Equity | E5: =SUM(E6:E7) -> 250000 | F5: =SUM(F6:F7) -> 219830.44 | G5: =SUM(G6:G7) -> 1165192.7 | H5: =SUM(H6:H7) -> 1116493.6 | I5: =SUM(I6:I7) -> 1056426.5 | J5: =I5 -> 1056426.5 | K5: =SUM(K6:K7) -> 987426.5 | L5: =SUM(L6:L7) -> 4918426.5 | M5: =SUM(M6:M7) -> 4464159.9 | N5: =SUM(N6:N7) -> 3961393.4 | O5: =N5 -> 3961393.4 | P5: =SUM(P6:P7) -> 3570814.6 | Q5: =SUM(Q6:Q7) -> 3287833 | R5: =SUM(R6:R7) -> 3088700.9 | S5: =SUM(S6:S7) -> 3035025.3 | T5: =S5 -> 3035025.3 | U5: =SUM(U6:U7) -> 3011091.3 | V5: =SUM(V6:V7) -> 3100062 | W5: =SUM(W6:W7) -> 3409685 | X5: =SUM(X6:X7) -> 4052373.3 | Y5: =X5 -> 4052373.3 | Z5: =SUM(Z6:Z7) -> 5325107.9 | AA5: =SUM(AA6:AA7) -> 6861103.6 | AB5: =SUM(AB6:AB7) -> 8969906.9 | AC5: =SUM(AC6:AC7) -> 11951387 | AD5: =AC5 -> 11951387 | AE5: =SUM(AE6:AE7) -> 11951387 | AF5: =SUM(AF6:AF7) -> 0 | AG5: =SUM(AG6:AG7) -> 0 | AH5: =SUM(AH6:AH7) -> 0 | AI5: =AH5 -> 0
C6: Paid-up Capital | E6: ='Assumptions & Sensitivity'!D86 -> 250000 | F6: ='Equity Schedule'!F12 -> 250000 | G6: ='Equity Schedule'!G12 -> 1250000 | H6: ='Equity Schedule'!H12 -> 1250000 | I6: ='Equity Schedule'!I12 -> 1250000 | J6: =I6 -> 1250000 | K6: ='Equity Schedule'!K12 -> 1250000 | L6: ='Equity Schedule'!L12 -> 5250000 | M6: ='Equity Schedule'!M12 -> 5250000 | N6: ='Equity Schedule'!N12 -> 5250000 | O6: =N6 -> 5250000 | P6: ='Equity Schedule'!P12 -> 5250000 | Q6: ='Equity Schedule'!Q12 -> 5250000 | R6: ='Equity Schedule'!R12 -> 5250000 | S6: ='Equity Schedule'!S12 -> 5250000 | T6: =S6 -> 5250000 | U6: ='Equity Schedule'!U12 -> 5250000 | V6: ='Equity Schedule'!V12 -> 5250000 | W6: ='Equity Schedule'!W12 -> 5250000 | X6: ='Equity Schedule'!X12 -> 5250000 | Y6: =X6 -> 5250000 | Z6: ='Equity Schedule'!Z12 -> 5250000 | AA6: ='Equity Schedule'!AA12 -> 5250000 | AB6: ='Equity Schedule'!AB12 -> 5250000 | AC6: ='Equity Schedule'!AC12 -> 5250000 | AD6: =AC6 -> 5250000 | AE6: ='Equity Schedule'!AD12 -> 5250000 | AF6: ='Equity Schedule'!AE12 -> 0 | AG6: ='Equity Schedule'!AF12 -> 0 | AH6: ='Equity Schedule'!AG12 -> 0 | AI6: =AH6 -> 0
C7: [+] Retained Earnings | E7: ='Equity Schedule'!E17 -> 0 | F7: ='Equity Schedule'!F17 -> -30169.56 | G7: ='Equity Schedule'!G17 -> -84807.26 | H7: ='Equity Schedule'!H17 -> -133506.36 | I7: ='Equity Schedule'!I17 -> -193573.5 | J7: =I7 -> -193573.5 | K7: ='Equity Schedule'!K17 -> -262573.5 | L7: ='Equity Schedule'!L17 -> -331573.5 | M7: ='Equity Schedule'!M17 -> -785840.06 | N7: ='Equity Schedule'!N17 -> -1288606.6 | O7: =N7 -> -1288606.6 | P7: ='Equity Schedule'!P17 -> -1679185.4 | Q7: ='Equity Schedule'!Q17 -> -1962167 | R7: ='Equity Schedule'!R17 -> -2161299.1 | S7: ='Equity Schedule'!S17 -> -2214974.7 | T7: =S7 -> -2214974.7 | U7: ='Equity Schedule'!U17 -> -2238908.7 | V7: ='Equity Schedule'!V17 -> -2149938 | W7: ='Equity Schedule'!W17 -> -1840315 | X7: ='Equity Schedule'!X17 -> -1197626.7 | Y7: =X7 -> -1197626.7 | Z7: ='Equity Schedule'!Z17 -> 75107.861 | AA7: ='Equity Schedule'!AA17 -> 1611103.6 | AB7: ='Equity Schedule'!AB17 -> 3719906.9 | AC7: ='Equity Schedule'!AC17 -> 6701386.9 | AD7: =AC7 -> 6701386.9 | AE7: ='Equity Schedule'!AD17 -> 6701386.9 | AF7: ='Equity Schedule'!AE17 -> 0 | AG7: ='Equity Schedule'!AF17 -> 0 | AH7: ='Equity Schedule'!AG17 -> 0 | AI7: =AH7 -> 0
B8: Total Liabilities & Shareholders' Equity | E8: =E3+E5 -> 250000 | F8: =F3+F5 -> 219830.44 | G8: =G3+G5 -> 1165192.7 | H8: =H3+H5 -> 1116493.6 | I8: =I3+I5 -> 1056426.5 | J8: =I8 -> 1056426.5 | K8: =K3+K5 -> 1003349.6 | L8: =L3+L5 -> 4934349.6 | M8: =M3+M5 -> 4568990.7 | N8: =N3+N5 -> 4077416.4 | O8: =N8 -> 4077416.4 | P8: =P3+P5 -> 3690695.9 | Q8: =Q3+Q5 -> 3407221.5 | R8: =R3+R5 -> 3219331.6 | S8: =S3+S5 -> 3170989.8 | T8: =S8 -> 3170989.8 | U8: =U3+U5 -> 3196497.1 | V8: =V3+V5 -> 3344850.9 | W8: =W3+W5 -> 3735779.2 | X8: =X3+X5 -> 4456041.7 | Y8: =X8 -> 4456041.7 | Z8: =Z3+Z5 -> 5868376.6 | AA8: =AA3+AA5 -> 7506477 | AB8: =AB3+AB5 -> 9776174.5 | AC8: =AC3+AC5 -> 12929417 | AD8: =AC8 -> 12929417 | AE8: =AE3+AE5 -> 14924327 | AF8: =AF3+AF5 -> 1223789.5 | AG8: =AG3+AG5 -> 1404845 | AH8: =AH3+AH5 -> 1657161.5 | AI8: =AH8 -> 1657161.5
B9: Current Assets | E9: =SUM(E10:E11) -> 250000 | F9: =SUM(F10:F11) -> 219830.44 | G9: =SUM(G10:G11) -> 1165192.7 | H9: =SUM(H10:H11) -> 1116493.6 | I9: =SUM(I10:I11) -> 1056426.5 | J9: =I9 -> 1056426.5 | K9: =SUM(K10:K11) -> 1003349.6 | L9: =SUM(L10:L11) -> 4934349.6 | M9: =SUM(M10:M11) -> 4568990.7 | N9: =SUM(N10:N11) -> 4077416.4 | O9: =N9 -> 4077416.4 | P9: =SUM(P10:P11) -> 3690695.9 | Q9: =SUM(Q10:Q11) -> 3407221.5 | R9: =SUM(R10:R11) -> 3219331.6 | S9: =SUM(S10:S11) -> 3170989.8 | T9: =S9 -> 3170989.8 | U9: =SUM(U10:U11) -> 3196497.1 | V9: =SUM(V10:V11) -> 3344850.9 | W9: =SUM(W10:W11) -> 3735779.2 | X9: =SUM(X10:X11) -> 4456041.7 | Y9: =X9 -> 4456041.7 | Z9: =SUM(Z10:Z11) -> 5868376.6 | AA9: =SUM(AA10:AA11) -> 7506477 | AB9: =SUM(AB10:AB11) -> 9776174.5 | AC9: =SUM(AC10:AC11) -> 12929417 | AD9: =AC9 -> 12929417 | AE9: =SUM(AE10:AE11) -> 17726443 | AF9: =SUM(AF10:AF11) -> 21656241 | AG9: =SUM(AG10:AG11) -> 25934380 | AH9: =SUM(AH10:AH11) -> 31539714 | AI9: =AH9 -> 31539714
B10: Cash & Cash Equivalent | E10: =E8 -> 250000 | F10: =CFS!D13 -> 219830.44 | G10: =CFS!E13 -> 1165192.7 | H10: =CFS!F13 -> 1116493.6 | I10: =CFS!G13 -> 1056426.5 | J10: =I10 -> 1056426.5 | K10: =CFS!I13 -> 1003349.6 | L10: =CFS!J13 -> 4934349.6 | M10: =CFS!K13 -> 4568990.7 | N10: =CFS!L13 -> 4077416.4 | O10: =N10 -> 4077416.4 | P10: =CFS!N13 -> 3648199.1 | Q10: =CFS!O13 -> 3329957.1 | R10: =CFS!P13 -> 3098364.2 | S10: =CFS!Q13 -> 2994450.1 | T10: =S10 -> 2994450.1 | U10: =CFS!S13 -> 2939522 | V10: =CFS!T13 -> 2965821.4 | W10: =CFS!U13 -> 3167856.8 | X10: =CFS!V13 -> 3667497.3 | Y10: =X10 -> 3667497.3 | Z10: =CFS!X13 -> 4666113.6 | AA10: =CFS!Y13 -> 5943537.5 | AB10: =CFS!Z13 -> 7744351.1 | AC10: =CFS!AA13 -> 10288047 | AD10: =AC10 -> 10288047 | AE10: =CFS!AB13 -> 10288047 | AF10: =CFS!AC13 -> 18187060 | AG10: =CFS!AD13 -> 21728883 | AH10: =CFS!AE13 -> 26442142 | AI10: =AH10 -> 26442142
B11: Accounts Receivables | E11: 0 | F11: =('Assumptions & Sensitivity'!$D$83/91)*'P&L'!E3 -> 0 | G11: =('Assumptions & Sensitivity'!$D$83/91)*'P&L'!F3 -> 0 | H11: =('Assumptions & Sensitivity'!$D$83/91)*'P&L'!G3 -> 0 | I11: =('Assumptions & Sensitivity'!$D$83/91)*'P&L'!H3 -> 0 | J11: =I11 -> 0 | K11: =('Assumptions & Sensitivity'!$D$83/91)*'P&L'!J3 -> 0 | L11: =('Assumptions & Sensitivity'!$D$83/91)*'P&L'!K3 -> 0 | M11: =('Assumptions & Sensitivity'!$D$83/91)*'P&L'!L3 -> 0 | N11: =('Assumptions & Sensitivity'!$D$83/91)*'P&L'!M3 -> 0 | O11: =N11 -> 0 | P11: =('Assumptions & Sensitivity'!$D$83/91)*'P&L'!O3 -> 42496.873 | Q11: =('Assumptions & Sensitivity'!$D$83/91)*'P&L'!P3 -> 77264.337 | R11: =('Assumptions & Sensitivity'!$D$83/91)*'P&L'!Q3 -> 120967.42 | S11: =('Assumptions & Sensitivity'!$D$83/91)*'P&L'!R3 -> 176539.79 | T11: =S11 -> 176539.79 | U11: =('Assumptions & Sensitivity'!$D$83/91)*'P&L'!T3 -> 256975.06 | V11: =('Assumptions & Sensitivity'!$D$83/91)*'P&L'!U3 -> 379029.42 | W11: =('Assumptions & Sensitivity'!$D$83/91)*'P&L'!V3 -> 567922.32 | X11: =('Assumptions & Sensitivity'!$D$83/91)*'P&L'!W3 -> 788544.45 | Y11: =X11 -> 788544.45 | Z11: =('Assumptions & Sensitivity'!$D$83/91)*'P&L'!Y3 -> 1202263 | AA11: =('Assumptions & Sensitivity'!$D$83/91)*'P&L'!Z3 -> 1562939.6 | AB11: =('Assumptions & Sensitivity'!$D$83/91)*'P&L'!AA3 -> 2031823.4 | AC11: =('Assumptions & Sensitivity'!$D$83/91)*'P&L'!AB3 -> 2641370.5 | AD11: =AC11 -> 2641370.5 | AE11: =('Assumptions & Sensitivity'!$D$83/91)*'P&L'!AC3 -> 7438396.5 | AF11: =('Assumptions & Sensitivity'!$D$83/91)*'P&L'!AD3 -> 3469180.3 | AG11: =('Assumptions & Sensitivity'!$D$83/91)*'P&L'!AE3 -> 4205497.2 | AH11: =('Assumptions & Sensitivity'!$D$83/91)*'P&L'!AF3 -> 5097572.3 | AI11: =AH11 -> 5097572.3
B12: Total Assets | E12: =E9 -> 250000 | F12: =F9 -> 219830.44 | G12: =G9 -> 1165192.7 | H12: =H9 -> 1116493.6 | I12: =I9 -> 1056426.5 | J12: =I12 -> 1056426.5 | K12: =K9 -> 1003349.6 | L12: =L9 -> 4934349.6 | M12: =M9 -> 4568990.7 | N12: =N9 -> 4077416.4 | O12: =N12 -> 4077416.4 | P12: =P9 -> 3690695.9 | Q12: =Q9 -> 3407221.5 | R12: =R9 -> 3219331.6 | S12: =S9 -> 3170989.8 | T12: =S12 -> 3170989.8 | U12: =U9 -> 3196497.1 | V12: =V9 -> 3344850.9 | W12: =W9 -> 3735779.2 | X12: =X9 -> 4456041.7 | Y12: =X12 -> 4456041.7 | Z12: =Z9 -> 5868376.6 | AA12: =AA9 -> 7506477 | AB12: =AB9 -> 9776174.5 | AC12: =AC9 -> 12929417 | AD12: =AC12 -> 12929417 | AE12: =AE9 -> 17726443 | AF12: =AF9 -> 21656241 | AG12: =AG9 -> 25934380 | AH12: =AH9 -> 31539714 | AI12: =AH12 -> 31539714
C14: Balance Check | E14: =ABS(E8-E12)<1 -> TRUE | F14: =ABS(F8-F12)<1 -> TRUE | G14: =ABS(G8-G12)<1 -> TRUE | H14: =ABS(H8-H12)<1 -> TRUE | I14: =ABS(I8-I12)<1 -> TRUE | J14: =ABS(J8-J12)<1 -> TRUE | K14: =ABS(K8-K12)<1 -> TRUE | L14: =ABS(L8-L12)<1 -> TRUE | ... AC14: =ABS(AC8-AC12)<1 -> TRUE | AD14: =ABS(AM8-AM12)<1 -> TRUE | AE14: =ABS(AD8-AD12)<1 -> TRUE | AF14: =ABS(AJ8-AJ12)<1 -> TRUE | AG14: =ABS(AK8-AK12)<1 -> TRUE | AH14: =ABS(AL8-AL12)<1 -> TRUE | AI14: =ABS(AR8-AR12)<1 -> TRUE
E15: =E12-E8 -> 0 | F15: =F12-F8 -> 0 | G15: =G12-G8 -> 0 | H15: =H12-H8 -> 0 | I15: =I12-I8 -> 0 | J15: =J12-J8 -> 0 | K15: =K12-K8 -> 0 | L15: =L12-L8 -> 0 | ... AC15: =AC12-AC8 -> 0 | AD15: =AM12-AM8 -> 0 | AE15: =AD12-AD8 -> 0 | AF15: =AJ12-AJ8 -> 0 | AG15: =AK12-AK8 -> 0 | AH15: =AL12-AL8 -> 0 | AI15: =AR12-AR8 -> 0

Sheet CFS
B2: Cashflow Statement (in US$) | D2: Q1-17 | E2: Q2-17 | F2: Q3-17 | G2: Q4-17 | H2: 2017 | I2: Q1-18 | J2: Q2-18 | K2: Q3-18 | L2: Q4-18 | M2: 2018 | N2: Q1-19 | O2: Q2-19 | P2: Q3-19 | Q2: Q4-19 | R2: 2019 | S2: Q1-20 | T2: Q2-20 | U2: Q3-20 | V2: Q4-20 | W2: 2020 | X2: Q1-21 | Y2: Q2-21 | Z2: Q3-21 | AA2: Q4-21 | AB2: 2021 | AC2: Q1-22 | AD2: Q2-22 | AE2: Q3-22 | AF2: Q4-22 | AG2: 2022
