Workbook

Sheet Inputs
A1: Legend
A3: Input
A4: Reference to Other Sheet
A5: Output/Calculation
A7: Assumptions
A8: Cutomer Baseline | B8: Input | C8: Calculation | D8: Notes
A9: New | B9: 62 | C9: =AVERAGE(Model!D4:I4) -> 62.166667 | D9: 6 - month average. Growth based on user input. Assumed new customers relatively constant based on trends.
A10: Legacy to New Team | B10: 3 | C10: =AVERAGE(Model!D5:I5) -> 2.6666667 | D10: 6 - month average. Historical figures relatively flat.
A11: Expansion | B11: 69 | C11: =Growth_Analysis!$J$15 -> 69 | D11: Modeled growth based on linear equation. More expansion opportunities as the base grows. Refer to Growth Analysis for expanded projection.
A12: Contraction | B12: 40 | C12: =Growth_Analysis!$J$16 -> 40 | D12: Modeled growth based on linear equation. More companies will contract the larger the customer base. Refer to Growth Analysis for expanded projection.
A13: Old Team to New Team | B13: 1 | C13: =AVERAGE(Model!F9:I9) -> 1 | D13: 6 - month average. Historical figures relatively flat.
A14: % Churn-Failed Reactivation | B14: 0.75 | C14: =AVERAGE(Model!F22:I22) -> 0.22222222 | D14: 2018 average (YTD). Opportunity to improve. Churn related to failed credit card payment needs to be addressed appropriately
A15: Churn % (Monthly) | B15: =C15 -> 0.0048816491 | C15: =AVERAGE(Model!F43:I43) -> 0.0048816491 | D15: 2018 average (YTD). Maintain low Churn percentage. Churn % remains relatively flat, but will grow overall as more customers are onboarded.
A16: Churn-Failed % (Monthly) | B16: 0.005 | C16: =AVERAGE(Model!F44:I44) -> 0.015580078 | D16: 2018 average (YTD). Opportunity to improve payments
A18: Growth (MoM) | B18: Input
A19: New | B19: 0.03
A20: Legacy to New Team | B20: 0
A21: Old Team to New Team | B21: 0
A23: Pricing | B23: Input | C23: Calculation
A24: ARR of New Customer | B24: 2451.3962 | C24: =AVERAGE(Summary!F83:I83) -> 2451.3962
A25: ARR of Legacy to New Team | B25: 2476 | C25: =AVERAGE(Summary!F84:I84) -> 2476
A26: ARR No Change | B26: 0 | C26: =AVERAGE(Summary!F85:I85) -> 0
A27: Increase in ARR of Expansion | B27: 2207.1889 | C27: =AVERAGE(Summary!F86:I86) -> 2207.1889
A28: Decrease in ARR of Contraction | B28: -2800.3313 | C28: =AVERAGE(Summary!F87:I87) -> -2800.3313
A29: Increase in ARR Old Team to New Team | B29: 1360 | C29: =AVERAGE(Summary!F88:I88) -> 1360
A30: Increase in ARR Churn - Failed Reactivation | B30: 2088 | C30: =AVERAGE(Summary!F89:I89) -> 2088
A31: Churn Decrease in ARR | B31: -5536 | C31: =AVERAGE(Summary!F90:I90) -> -5536
A32: Churn - Failed Decrease in ARR | B32: -3229.75 | C32: =AVERAGE(Summary!F91:I91) -> -3229.75
A34: Methodology
A35: 1) Categorized Customers by change_type and by month
A36: 2.) Plotted YTD figures to determine trends and performed a simple linear regression analysis for customer type
A37: 3.) Determined Starting ARR, Change in ARR, and Ending ARR by Customer
A38: 4.) Removed Outlier Data to normalize YTD figures. Removed client ID# 39NTHthWY3. Fell outside the normal range of all other figures. Assumption that was an error or a one-time charge.
A39: 5.) Calculated pricing based on YTD averages and by change_type

Sheet Summary
B33: =Model!B2 -> Adjusted Actuals * | C33: =Model!C2 -> 0 | D33: =Model!D2 -> 0 | E33: =Model!E2 -> 0 | F33: =Model!F2 -> 0 | G33: =Model!G2 -> 0 | H33: =Model!H2 -> 0 | I33: =Model!I2 -> 0 | J33: =Model!J2 -> Projected | S33: =Model!S2 -> Apr 18' - Dec 18' CMGR | T33: =Model!T2 -> 2H' CMGR
A34: =Model!A3 -> Customer Type | B34: =Model!B3 -> 42979 | C34: =Model!C3 -> 43009 | D34: =Model!D3 -> 43040 | E34: =Model!E3 -> 43070 | F34: =Model!F3 -> 43101 | G34: =Model!G3 -> 43132 | H34: =Model!H3 -> 43160 | ... Q34: =Model!Q3 -> 43435 | S34: =Model!S3 -> 0 | T34: =Model!T3 -> 0
A35: =Model!A4 -> New | B35: =Model!B4 -> 2 | C35: =Model!C4 -> 26 | D35: =Model!D4 -> 62 | E35: =Model!E4 -> 85 | F35: =Model!F4 -> 51 | G35: =Model!G4 -> 50 | H35: =Model!H4 -> 61 | ... Q35: =Model!Q4 -> 76 | S35: =Model!S4 -> 0.021713666 | T35: =Model!T4 -> 0.029055827
A36: =Model!A5 -> Legacy to New Team | B36: =Model!B5 -> 0 | C36: =Model!C5 -> 1 | D36: =Model!D5 -> 4 | E36: =Model!E5 -> 4 | F36: =Model!F5 -> 5 | G36: =Model!G5 -> 2 | H36: =Model!H5 -> 1 | ... Q36: =Model!Q5 -> 3 | S36: =Model!S5 -> N/A | T36: =Model!T5 -> 8.3526939e-15
A37: =Model!A6 -> No Change | B37: =Model!B6 -> 0 | C37: =Model!C6 -> 1 | D37: =Model!D6 -> 22 | E37: =Model!E6 -> 67 | F37: =Model!F6 -> 131 | G37: =Model!G6 -> 169 | H37: =Model!H6 -> 190 | ... Q37: =Model!Q6 -> 599 | S37: =Model!S6 -> 0.13146271 | T37: =Model!T6 -> 0.1190629
A38: =Model!A7 -> Expansion | B38: =Model!B7 -> 0 | C38: =Model!C7 -> 0 | D38: =Model!D7 -> 5 | E38: =Model!E7 -> 14 | F38: =Model!F7 -> 24 | G38: =Model!G7 -> 44 | H38: =Model!H7 -> 41 | ... Q38: =Model!Q7 -> 145 | S38: =Model!S7 -> 0.11661149 | T38: =Model!T7 -> 0.10419642
A39: =Model!A8 -> Contraction | B39: =Model!B8 -> 0 | C39: =Model!C8 -> 0 | D39: =Model!D8 -> 2 | E39: =Model!E8 -> 14 | F39: =Model!F8 -> 26 | G39: =Model!G8 -> 14 | H39: =Model!H8 -> 34 | ... Q39: =Model!Q8 -> 79 | S39: =Model!S8 -> 0.12404365 | T39: =Model!T8 -> 0.094321361
A40: =Model!A9 -> Old Team to New Team | B40: =Model!B9 -> 0 | C40: =Model!C9 -> 0 | D40: =Model!D9 -> 0 | E40: =Model!E9 -> 1 | F40: =Model!F9 -> 0 | G40: =Model!G9 -> 3 | H40: =Model!H9 -> 0 | ... Q40: =Model!Q9 -> 1 | S40: =Model!S9 -> 3.1899074e-12 | T40: =Model!T9 -> 8.2329818e-15
A41: =Model!A10 -> Churn-Failed Reactivation | B41: =Model!B10 -> 0 | C41: =Model!C10 -> 0 | D41: =Model!D10 -> 0 | E41: =Model!E10 -> 0 | F41: =Model!F10 -> 0 | G41: =Model!G10 -> 1 | H41: =Model!H10 -> 1 | ... Q41: =Model!Q10 -> 3 | S41: =Model!S10 -> N/A | T41: =Model!T10 -> 0.069913194
A42: =Model!A11 -> Total Customers | B42: =Model!B11 -> 2 | C42: =Model!C11 -> 28 | D42: =Model!D11 -> 95 | E42: =Model!E11 -> 185 | F42: =Model!F11 -> 237 | G42: =Model!G11 -> 283 | H42: =Model!H11 -> 328 | ... Q42: =Model!Q11 -> 906 | S42: =Model!S11 -> 0.11509309 | T42: =Model!T11 -> 0.10377803
A43: =Model!A12 -> Churn | B43: =Model!B12 -> 0 | C43: =Model!C12 -> 1 | D43: =Model!D12 -> 1 | E43: =Model!E12 -> 3 | F43: =Model!F12 -> 0 | G43: =Model!G12 -> 3 | H43: =Model!H12 -> 1 | ... Q43: =Model!Q12 -> 4 | S43: =Model!S12 -> 0.18920712 | T43: =Model!T12 -> 0.12246205
A44: =Model!A13 -> Churn-Failed | B44: =Model!B13 -> 0 | C44: =Model!C13 -> 0 | D44: =Model!D13 -> 1 | E44: =Model!E13 -> 0 | F44: =Model!F13 -> 3 | G44: =Model!G13 -> 3 | H44: =Model!H13 -> 4 | ... Q44: =Model!Q13 -> 4 | S44: =Model!S13 -> -0.049420175 | T44: =Model!T13 -> 0.12246205
A45: =Model!A14 -> Total Churn | B45: =Model!B14 -> 0 | C45: =Model!C14 -> 1 | D45: =Model!D14 -> 2 | E45: =Model!E14 -> 3 | F45: =Model!F14 -> 3 | G45: =Model!G14 -> 6 | H45: =Model!H14 -> 5 | ... Q45: =Model!Q14 -> 8 | S45: =Model!S14 -> 0.016831504 | T45: =Model!T14 -> 0.12246205
A46: =Model!A15 -> Total Customers | B46: =Model!B15 -> 2 | C46: =Model!C15 -> 27 | D46: =Model!D15 -> 93 | E46: =Model!E15 -> 182 | F46: =Model!F15 -> 234 | G46: =Model!G15 -> 277 | H46: =Model!H15 -> 323 | ... Q46: =Model!Q15 -> 898 | S46: =Model!S15 -> 0.11645616 | T46: =Model!T15 -> 0.10362109
A48: =Model!A53 -> Revenue - Starting ARR
A49: =Model!A54 -> New | B49: =Model!B54 -> 0 | C49: =Model!C54 -> 0 | D49: =Model!D54 -> 0 | E49: =Model!E54 -> 0 | F49: =Model!F54 -> 0 | G49: =Model!G54 -> 0 | H49: =Model!H54 -> 0 | ... Q49: =Model!Q54 -> 0 | S49: =Model!S54 -> N/A | T49: =Model!T54 -> N/A
A50: =Model!A55 -> Legacy to New Team | B50: =Model!B55 -> 0 | C50: =Model!C55 -> 0 | D50: =Model!D55 -> 0 | E50: =Model!E55 -> 0 | F50: =Model!F55 -> 0 | G50: =Model!G55 -> 0 | H50: =Model!H55 -> 0 | ... Q50: =Model!Q55 -> 0 | S50: =Model!S55 -> N/A | T50: =Model!T55 -> N/A
A51: =Model!A56 -> No Change | B51: =Model!B56 -> 0 | C51: =Model!C56 -> 1200 | D51: =Model!D56 -> 29520 | E51: =Model!E56 -> 94128 | F51: =Model!F56 -> 187908 | G51: =Model!G56 -> 241536 | H51: =Model!H56 -> 277992 | ... Q51: =Model!Q56 -> 880647.32 | S51: =Model!S56 -> 0.12954211 | T51: =Model!T56 -> 0.10802422
A52: =Model!A57 -> Expansion | B52: =Model!B57 -> 0 | C52: =Model!C57 -> 0 | D52: =Model!D57 -> 25668 | E52: =Model!E57 -> 86640 | F52: =Model!F57 -> 151416 | G52: =Model!G57 -> 224292 | H52: =Model!H57 -> 184872 | ... Q52: =Model!Q57 -> 799527.82 | S52: =Model!S57 -> 0.12954211 | T52: =Model!T57 -> 0.10802422
A53: =Model!A58 -> Contraction | B53: =Model!B58 -> 0 | C53: =Model!C58 -> 0 | D53: =Model!D58 -> 31236 | E53: =Model!E58 -> 245712 | F53: =Model!F58 -> 227472 | G53: =Model!G58 -> 119220 | H53: =Model!H58 -> 223116 | ... Q53: =Model!Q58 -> 444727.69 | S53: =Model!S58 -> 0.12954211 | T53: =Model!T58 -> 0.10802422
A54: =Model!A59 -> Old Team to New Team | B54: =Model!B59 -> 0 | C54: =Model!C59 -> 0 | D54: =Model!D59 -> 0 | E54: =Model!E59 -> 0 | F54: =Model!F59 -> 0 | G54: =Model!G59 -> 0 | H54: =Model!H59 -> 0 | ... Q54: =Model!Q59 -> 0 | S54: =Model!S59 -> N/A | T54: =Model!T59 -> N/A
A55: =Model!A60 -> Churn-Failed Reactivation | B55: =Model!B60 -> 0 | C55: =Model!C60 -> 0 | D55: =Model!D60 -> 0 | E55: =Model!E60 -> 0 | F55: =Model!F60 -> 0 | G55: =Model!G60 -> 0 | H55: =Model!H60 -> 0 | ... Q55: =Model!Q60 -> 0 | S55: =Model!S60 -> N/A | T55: =Model!T60 -> N/A
A56: =Model!A61 -> Churn | B56: =Model!B61 -> 0 | C56: =Model!C61 -> 9804 | D56: =Model!D61 -> 1728 | E56: =Model!E61 -> 14712 | F56: =Model!F61 -> 0 | G56: =Model!G61 -> 4752 | H56: =Model!H61 -> 1440 | ... Q56: =Model!Q61 -> 22144 | S56: =Model!S61 -> 0.062988461 | T56: =Model!T61 -> 0.12246205
A57: =Model!A62 -> Churn-Failed | B57: =Model!B62 -> 0 | C57: =Model!C62 -> 0 | D57: =Model!D62 -> 1440 | E57: =Model!E62 -> 0 | F57: =Model!F62 -> 7380 | G57: =Model!G62 -> 4320 | H57: =Model!H62 -> 17412 | ... Q57: =Model!Q62 -> 12919 | S57: =Model!S62 -> -0.09214474 | T57: =Model!T62 -> 0.12246205
A58: =Model!A63 -> Total Starting ARR | B58: =Model!B63 -> 0 | C58: =Model!C63 -> 11004 | D58: =Model!D63 -> 89592 | E58: =Model!E63 -> 441192 | F58: =Model!F63 -> 574176 | G58: =Model!G63 -> 594120 | H58: =Model!H63 -> 704832 | ... Q58: =Model!Q63 -> 2159965.8 | S58: =Model!S63 -> 0.12472559 | T58: =Model!T63 -> 0.10824842
A59: =Model!A65 -> Revenue - Change in ARR | S59: =Model!S65 -> 0 | T59: =Model!T65 -> 0
A60: =Model!A66 -> New | B60: =Model!B66 -> 11004 | C60: =Model!C66 -> 81816 | D60: =Model!D66 -> 320772 | E60: =Model!E66 -> 195756 | F60: =Model!F66 -> 80688 | G60: =Model!G66 -> 130092 | H60: =Model!H66 -> 173507 | ... Q60: =Model!Q66 -> 186306.11 | S60: =Model!S66 -> 0.0058981707 | T60: =Model!T66 -> 0.029055827
A61: =Model!A67 -> Legacy to New Team | B61: =Model!B67 -> 0 | C61: =Model!C67 -> 3456 | D61: =Model!D67 -> 38232 | E61: =Model!E67 -> 18960 | F61: =Model!F67 -> 20220 | G61: =Model!G67 -> 3888 | H61: =Model!H67 -> 1440 | ... Q61: =Model!Q67 -> 7428 | S61: =Model!S67 -> N/A | T61: =Model!T67 -> 8.3301817e-15
A62: =Model!A68 -> No Change | B62: =Model!B68 -> 0 | C62: =Model!C68 -> 0 | D62: =Model!D68 -> 0 | E62: =Model!E68 -> 0 | F62: =Model!F68 -> 0 | G62: =Model!G68 -> 0 | H62: =Model!H68 -> 0 | ... Q62: =Model!Q68 -> 0 | S62: =Model!S68 -> N/A | T62: =Model!T68 -> N/A
A63: =Model!A69 -> Expansion | B63: =Model!B69 -> 0 | C63: =Model!C69 -> 0 | D63: =Model!D69 -> 16200 | E63: =Model!E69 -> 82008 | F63: =Model!F69 -> 73272 | G63: =Model!G69 -> 98016 | H63: =Model!H69 -> 68712 | ... Q63: =Model!Q69 -> 320042.39 | S63: =Model!S69 -> 0.13982327 | T63: =Model!T69 -> 0.10419642
A64: =Model!A70 -> Contraction | B64: =Model!B70 -> 0 | C64: =Model!C70 -> 0 | D64: =Model!D70 -> -8976 | E64: =Model!E70 -> -143112 | F64: =Model!F70 -> -118032 | G64: =Model!G70 -> -54744 | H64: =Model!H70 -> -43704 | ... Q64: =Model!Q70 -> -221226.17 | S64: =Model!S70 -> 0.21876506 | T64: =Model!T70 -> 0.094321361
A65: =Model!A71 -> Old Team to New Team | B65: =Model!B71 -> 0 | C65: =Model!C71 -> 0 | D65: =Model!D71 -> 0 | E65: =Model!E71 -> 1200 | F65: =Model!F71 -> 0 | G65: =Model!G71 -> 3840 | H65: =Model!H71 -> 0 | ... Q65: =Model!Q71 -> 1360 | S65: =Model!S71 -> -0.0071193383 | T65: =Model!T71 -> 8.3593552e-15
A66: =Model!A72 -> Churn-Failed Reactivation | B66: =Model!B72 -> 0 | C66: =Model!C72 -> 0 | D66: =Model!D72 -> 0 | E66: =Model!E72 -> 0 | F66: =Model!F72 -> 0 | G66: =Model!G72 -> 1440 | H66: =Model!H72 -> 2736 | ... Q66: =Model!Q72 -> 6264 | S66: =Model!S72 -> N/A | T66: =Model!T72 -> 0.069913194
A67: =Model!A73 -> Churn | B67: =Model!B73 -> 0 | C67: =Model!C73 -> -9804 | D67: =Model!D73 -> -1728 | E67: =Model!E73 -> -14712 | F67: =Model!F73 -> 0 | G67: =Model!G73 -> -4752 | H67: =Model!H73 -> -1440 | ... Q67: =Model!Q73 -> -22144 | S67: =Model!S73 -> 0.062988461 | T67: =Model!T73 -> 0.12246205
A68: =Model!A74 -> Churn-Failed | B68: =Model!B74 -> 0 | C68: =Model!C74 -> 0 | D68: =Model!D74 -> -1440 | E68: =Model!E74 -> 0 | F68: =Model!F74 -> -7380 | G68: =Model!G74 -> -4320 | H68: =Model!H74 -> -17412 | ... Q68: =Model!Q74 -> -12919 | S68: =Model!S74 -> -0.09214474 | T68: =Model!T74 -> 0.12246205
A69: =Model!A75 -> Total Change in ARR | B69: =Model!B75 -> 11004 | C69: =Model!C75 -> 75468 | D69: =Model!D75 -> 363060 | E69: =Model!E75 -> 140100 | F69: =Model!F75 -> 48768 | G69: =Model!G75 -> 173460 | H69: =Model!H75 -> 183839 | ... Q69: =Model!Q75 -> 265111.32 | S69: =Model!S75 -> 0.032984318 | T69: =Model!T75 -> 0.048021379
A70: =Model!A77 -> Revenue - Ending ARR
A71: =Model!A78 -> New | B71: =Model!B78 -> 11004 | C71: =Model!C78 -> 81816 | D71: =Model!D78 -> 320772 | E71: =Model!E78 -> 195756 | F71: =Model!F78 -> 80688 | G71: =Model!G78 -> 130092 | H71: =Model!H78 -> 173507 | ... Q71: =Model!Q78 -> 186306.11 | S71: =Model!S78 -> 0.0058981707 | T71: =Model!T78 -> 0.029055827
A72: =Model!A79 -> Legacy to New Team | B72: =Model!B79 -> 0 | C72: =Model!C79 -> 3456 | D72: =Model!D79 -> 38232 | E72: =Model!E79 -> 18960 | F72: =Model!F79 -> 20220 | G72: =Model!G79 -> 3888 | H72: =Model!H79 -> 1440 | ... Q72: =Model!Q79 -> 7428 | S72: =Model!S79 -> N/A | T72: =Model!T79 -> 8.3301817e-15
A73: =Model!A80 -> No Change | B73: =Model!B80 -> 0 | C73: =Model!C80 -> 1200 | D73: =Model!D80 -> 29520 | E73: =Model!E80 -> 94128 | F73: =Model!F80 -> 187908 | G73: =Model!G80 -> 241536 | H73: =Model!H80 -> 277992 | ... Q73: =Model!Q80 -> 880647.32 | S73: =Model!S80 -> 0.12954211 | T73: =Model!T80 -> 0.10802422
...

Sheet Model
B2: Adjusted Actuals * | J2: Projected | S2: Apr 18' - Dec 18' CMGR | T2: 2H' CMGR
A3: Customer Type | B3: 42979 | C3: 43009 | D3: 43040 | E3: 43070 | F3: 43101 | G3: 43132 | H3: 43160 | I3: 43191 | J3: 43221 | K3: 43252 | L3: 43282 | M3: 43313 | N3: 43344 | O3: 43374 | P3: 43405 | Q3: 43435
A4: New | B4: =COUNTIFS('data set'!$E:$E,Model!$A4,'data set'!$B:$B,Model!B$3) -> 2 | C4: =COUNTIFS('data set'!$E:$E,Model!$A4,'data set'!$B:$B,Model!C$3) -> 26 | D4: =COUNTIFS('data set'!$E:$E,Model!$A4,'data set'!$B:$B,Model!D$3) -> 62 | E4: =COUNTIFS('data set'!$E:$E,Model!$A4,'data set'!$B:$B,Model!E$3) -> 85 | F4: =COUNTIFS('data set'!$E:$E,Model!$A4,'data set'!$B:$B,Model!F$3) -> 51 | G4: =COUNTIFS('data set'!$E:$E,Model!$A4,'data set'!$B:$B,Model!G$3) -> 50 | H4: =COUNTIFS('data set'!$E:$E,Model!$A4,'data set'!$B:$B,Model!H$3) -> 61 | I4: =COUNTIFS('data set'!$E:$E,Model!$A4,'data set'!$B:$B,Model!I$3) -> 64 | J4: =Inputs!B9 -> 62 | K4: =ROUND(J4*(1+K27),0) -> 64 | L4: =ROUND(K4*(1+L27),0) -> 66 | M4: =ROUND(L4*(1+M27),0) -> 68 | N4: =ROUND(M4*(1+N27),0) -> 70 | O4: =ROUND(N4*(1+O27),0) -> 72 | P4: =ROUND(O4*(1+P27),0) -> 74 | Q4: =ROUND(P4*(1+Q27),0) -> 76 | S4: =IFERROR(RATE(MONTH($Q$3)-MONTH($I$3),0,-I4,Q4),"N/A") -> 0.021713666 | T4: =IFERROR(RATE(MONTH($Q$3)-MONTH($K$3),0,-K4,Q4),"N/A") -> 0.029055827
A5: Legacy to New Team | B5: =COUNTIFS('data set'!$E:$E,Model!$A5,'data set'!$B:$B,Model!B$3) -> 0 | C5: =COUNTIFS('data set'!$E:$E,Model!$A5,'data set'!$B:$B,Model!C$3) -> 1 | D5: =COUNTIFS('data set'!$E:$E,Model!$A5,'data set'!$B:$B,Model!D$3) -> 4 | E5: =COUNTIFS('data set'!$E:$E,Model!$A5,'data set'!$B:$B,Model!E$3) -> 4 | F5: =COUNTIFS('data set'!$E:$E,Model!$A5,'data set'!$B:$B,Model!F$3) -> 5 | G5: =COUNTIFS('data set'!$E:$E,Model!$A5,'data set'!$B:$B,Model!G$3) -> 2 | H5: =COUNTIFS('data set'!$E:$E,Model!$A5,'data set'!$B:$B,Model!H$3) -> 1 | I5: =COUNTIFS('data set'!$E:$E,Model!$A5,'data set'!$B:$B,Model!I$3) -> 0 | J5: =Inputs!B10 -> 3 | K5: =ROUND(J5*(1+K28),0) -> 3 | L5: =ROUND(K5*(1+L28),0) -> 3 | M5: =ROUND(L5*(1+M28),0) -> 3 | N5: =ROUND(M5*(1+N28),0) -> 3 | O5: =ROUND(N5*(1+O28),0) -> 3 | P5: =ROUND(O5*(1+P28),0) -> 3 | Q5: =ROUND(P5*(1+Q28),0) -> 3 | S5: =IFERROR(RATE(MONTH($Q$3)-MONTH($I$3),0,-I5,Q5),"N/A") -> N/A | T5: =IFERROR(RATE(MONTH($Q$3)-MONTH($K$3),0,-K5,Q5),"N/A") -> 8.3526939e-15
A6: No Change | B6: =COUNTIFS('data set'!$E:$E,Model!$A6,'data set'!$B:$B,Model!B$3) -> 0 | C6: =COUNTIFS('data set'!$E:$E,Model!$A6,'data set'!$B:$B,Model!C$3) -> 1 | D6: =COUNTIFS('data set'!$E:$E,Model!$A6,'data set'!$B:$B,Model!D$3) -> 22 | E6: =COUNTIFS('data set'!$E:$E,Model!$A6,'data set'!$B:$B,Model!E$3) -> 67 | F6: =COUNTIFS('data set'!$E:$E,Model!$A6,'data set'!$B:$B,Model!F$3) -> 131 | G6: =COUNTIFS('data set'!$E:$E,Model!$A6,'data set'!$B:$B,Model!G$3) -> 169 | H6: =COUNTIFS('data set'!$E:$E,Model!$A6,'data set'!$B:$B,Model!H$3) -> 190 | I6: =COUNTIFS('data set'!$E:$E,Model!$A6,'data set'!$B:$B,Model!I$3) -> 223 | J6: =I15-J7-J8-J5-J9 -> 259 | K6: =J15-K7-K8-K5-K9 -> 305 | L6: =K15-L7-L8-L5-L9 -> 351 | M6: =L15-M7-M8-M5-M9 -> 398 | N6: =M15-N7-N8-N5-N9 -> 447 | O6: =N15-O7-O8-O5-O9 -> 496 | P6: =O15-P7-P8-P5-P9 -> 547 | Q6: =P15-Q7-Q8-Q5-Q9 -> 599 | S6: =IFERROR(RATE(MONTH($Q$3)-MONTH($I$3),0,-I6,Q6),"N/A") -> 0.13146271 | T6: =IFERROR(RATE(MONTH($Q$3)-MONTH($K$3),0,-K6,Q6),"N/A") -> 0.1190629
A7: Expansion | B7: =COUNTIFS('data set'!$E:$E,Model!$A7,'data set'!$B:$B,Model!B$3) -> 0 | C7: =COUNTIFS('data set'!$E:$E,Model!$A7,'data set'!$B:$B,Model!C$3) -> 0 | D7: =COUNTIFS('data set'!$E:$E,Model!$A7,'data set'!$B:$B,Model!D$3) -> 5 | E7: =COUNTIFS('data set'!$E:$E,Model!$A7,'data set'!$B:$B,Model!E$3) -> 14 | F7: =COUNTIFS('data set'!$E:$E,Model!$A7,'data set'!$B:$B,Model!F$3) -> 24 | G7: =COUNTIFS('data set'!$E:$E,Model!$A7,'data set'!$B:$B,Model!G$3) -> 44 | H7: =COUNTIFS('data set'!$E:$E,Model!$A7,'data set'!$B:$B,Model!H$3) -> 41 | I7: =COUNTIFS('data set'!$E:$E,Model!$A7,'data set'!$B:$B,Model!I$3) -> 60 | J7: =Growth_Analysis!J15 -> 69 | K7: =Growth_Analysis!K15 -> 80 | L7: =Growth_Analysis!L15 -> 91 | M7: =Growth_Analysis!M15 -> 102 | N7: =Growth_Analysis!N15 -> 112 | O7: =Growth_Analysis!O15 -> 123 | P7: =Growth_Analysis!P15 -> 134 | Q7: =Growth_Analysis!Q15 -> 145 | S7: =IFERROR(RATE(MONTH($Q$3)-MONTH($I$3),0,-I7,Q7),"N/A") -> 0.11661149 | T7: =IFERROR(RATE(MONTH($Q$3)-MONTH($K$3),0,-K7,Q7),"N/A") -> 0.10419642
A8: Contraction | B8: =COUNTIFS('data set'!$E:$E,Model!$A8,'data set'!$B:$B,Model!B$3) -> 0 | C8: =COUNTIFS('data set'!$E:$E,Model!$A8,'data set'!$B:$B,Model!C$3) -> 0 | D8: =COUNTIFS('data set'!$E:$E,Model!$A8,'data set'!$B:$B,Model!D$3) -> 2 | E8: =COUNTIFS('data set'!$E:$E,Model!$A8,'data set'!$B:$B,Model!E$3) -> 14 | F8: =COUNTIFS('data set'!$E:$E,Model!$A8,'data set'!$B:$B,Model!F$3) -> 26 | G8: =COUNTIFS('data set'!$E:$E,Model!$A8,'data set'!$B:$B,Model!G$3) -> 14 | H8: =COUNTIFS('data set'!$E:$E,Model!$A8,'data set'!$B:$B,Model!H$3) -> 34 | I8: =COUNTIFS('data set'!$E:$E,Model!$A8,'data set'!$B:$B,Model!I$3) -> 31 | J8: =Growth_Analysis!J16 -> 40 | K8: =Growth_Analysis!K16 -> 46 | L8: =Growth_Analysis!L16 -> 51 | M8: =Growth_Analysis!M16 -> 57 | N8: =Growth_Analysis!N16 -> 62 | O8: =Growth_Analysis!O16 -> 68 | P8: =Growth_Analysis!P16 -> 74 | Q8: =Growth_Analysis!Q16 -> 79 | S8: =IFERROR(RATE(MONTH($Q$3)-MONTH($I$3),0,-I8,Q8),"N/A") -> 0.12404365 | T8: =IFERROR(RATE(MONTH($Q$3)-MONTH($K$3),0,-K8,Q8),"N/A") -> 0.094321361
A9: Old Team to New Team | B9: =COUNTIFS('data set'!$E:$E,Model!$A9,'data set'!$B:$B,Model!B$3) -> 0 | C9: =COUNTIFS('data set'!$E:$E,Model!$A9,'data set'!$B:$B,Model!C$3) -> 0 | D9: =COUNTIFS('data set'!$E:$E,Model!$A9,'data set'!$B:$B,Model!D$3) -> 0 | E9: =COUNTIFS('data set'!$E:$E,Model!$A9,'data set'!$B:$B,Model!E$3) -> 1 | F9: =COUNTIFS('data set'!$E:$E,Model!$A9,'data set'!$B:$B,Model!F$3) -> 0 | G9: =COUNTIFS('data set'!$E:$E,Model!$A9,'data set'!$B:$B,Model!G$3) -> 3 | H9: =COUNTIFS('data set'!$E:$E,Model!$A9,'data set'!$B:$B,Model!H$3) -> 0 | I9: =COUNTIFS('data set'!$E:$E,Model!$A9,'data set'!$B:$B,Model!I$3) -> 1 | J9: =Inputs!B13 -> 1 | K9: =ROUND(J9*(1+K29),0) -> 1 | L9: =ROUND(K9*(1+L29),0) -> 1 | M9: =ROUND(L9*(1+M29),0) -> 1 | N9: =ROUND(M9*(1+N29),0) -> 1 | O9: =ROUND(N9*(1+O29),0) -> 1 | P9: =ROUND(O9*(1+P29),0) -> 1 | Q9: =ROUND(P9*(1+Q29),0) -> 1 | S9: =IFERROR(RATE(MONTH($Q$3)-MONTH($I$3),0,-I9,Q9),"N/A") -> 3.1899074e-12 | T9: =IFERROR(RATE(MONTH($Q$3)-MONTH($K$3),0,-K9,Q9),"N/A") -> 8.2329818e-15
A10: Churn-Failed Reactivation | B10: =COUNTIFS('data set'!$E:$E,Model!$A10,'data set'!$B:$B,Model!B$3) -> 0 | C10: =COUNTIFS('data set'!$E:$E,Model!$A10,'data set'!$B:$B,Model!C$3) -> 0 | D10: =COUNTIFS('data set'!$E:$E,Model!$A10,'data set'!$B:$B,Model!D$3) -> 0 | E10: =COUNTIFS('data set'!$E:$E,Model!$A10,'data set'!$B:$B,Model!E$3) -> 0 | F10: =COUNTIFS('data set'!$E:$E,Model!$A10,'data set'!$B:$B,Model!F$3) -> 0 | G10: =COUNTIFS('data set'!$E:$E,Model!$A10,'data set'!$B:$B,Model!G$3) -> 1 | H10: =COUNTIFS('data set'!$E:$E,Model!$A10,'data set'!$B:$B,Model!H$3) -> 1 | I10: =COUNTIFS('data set'!$E:$E,Model!$A10,'data set'!$B:$B,Model!I$3) -> 0 | J10: =ROUND(I13*J22,0) -> 5 | K10: =ROUND(J13*K22,0) -> 2 | L10: =ROUND(K13*L22,0) -> 2 | M10: =ROUND(L13*M22,0) -> 2 | N10: =ROUND(M13*N22,0) -> 2 | O10: =ROUND(N13*O22,0) -> 2 | P10: =ROUND(O13*P22,0) -> 2 | Q10: =ROUND(P13*Q22,0) -> 3 | S10: =IFERROR(RATE(MONTH($Q$3)-MONTH($I$3),0,-I10,Q10),"N/A") -> N/A | T10: =IFERROR(RATE(MONTH($Q$3)-MONTH($K$3),0,-K10,Q10),"N/A") -> 0.069913194
A11: Total Customers | B11: =SUM(B4:B10) -> 2 | C11: =SUM(C4:C10) -> 28 | D11: =SUM(D4:D10) -> 95 | E11: =SUM(E4:E10) -> 185 | F11: =SUM(F4:F10) -> 237 | G11: =SUM(G4:G10) -> 283 | H11: =SUM(H4:H10) -> 328 | I11: =SUM(I4:I10) -> 379 | ... Q11: =SUM(Q4:Q10) -> 906 | S11: =IFERROR(RATE(MONTH($Q$3)-MONTH($I$3),0,-I11,Q11),"N/A") -> 0.11509309 | T11: =IFERROR(RATE(MONTH($Q$3)-MONTH($K$3),0,-K11,Q11),"N/A") -> 0.10377803
A12: Churn | B12: =COUNTIFS('data set'!$E:$E,Model!$A12,'data set'!$B:$B,Model!B$3) -> 0 | C12: =COUNTIFS('data set'!$E:$E,Model!$A12,'data set'!$B:$B,Model!C$3) -> 1 | D12: =COUNTIFS('data set'!$E:$E,Model!$A12,'data set'!$B:$B,Model!D$3) -> 1 | E12: =COUNTIFS('data set'!$E:$E,Model!$A12,'data set'!$B:$B,Model!E$3) -> 3 | F12: =COUNTIFS('data set'!$E:$E,Model!$A12,'data set'!$B:$B,Model!F$3) -> 0 | G12: =COUNTIFS('data set'!$E:$E,Model!$A12,'data set'!$B:$B,Model!G$3) -> 3 | H12: =COUNTIFS('data set'!$E:$E,Model!$A12,'data set'!$B:$B,Model!H$3) -> 1 | I12: =COUNTIFS('data set'!$E:$E,Model!$A12,'data set'!$B:$B,Model!I$3) -> 1 | J12: =ROUND(I$15*J23,0) -> 2 | K12: =ROUND(J$15*K23,0) -> 2 | L12: =ROUND(K$15*L23,0) -> 2 | M12: =ROUND(L$15*M23,0) -> 3 | N12: =ROUND(M$15*N23,0) -> 3 | O12: =ROUND(N$15*O23,0) -> 3 | P12: =ROUND(O$15*P23,0) -> 4 | Q12: =ROUND(P$15*Q23,0) -> 4 | S12: =IFERROR(RATE(MONTH($Q$3)-MONTH($I$3),0,-I12,Q12),"N/A") -> 0.18920712 | T12: =IFERROR(RATE(MONTH($Q$3)-MONTH($K$3),0,-K12,Q12),"N/A") -> 0.12246205
A13: Churn-Failed | B13: =COUNTIFS('data set'!$E:$E,Model!$A13,'data set'!$B:$B,Model!B$3) -> 0 | C13: =COUNTIFS('data set'!$E:$E,Model!$A13,'data set'!$B:$B,Model!C$3) -> 0 | D13: =COUNTIFS('data set'!$E:$E,Model!$A13,'data set'!$B:$B,Model!D$3) -> 1 | E13: =COUNTIFS('data set'!$E:$E,Model!$A13,'data set'!$B:$B,Model!E$3) -> 0 | F13: =COUNTIFS('data set'!$E:$E,Model!$A13,'data set'!$B:$B,Model!F$3) -> 3 | G13: =COUNTIFS('data set'!$E:$E,Model!$A13,'data set'!$B:$B,Model!G$3) -> 3 | H13: =COUNTIFS('data set'!$E:$E,Model!$A13,'data set'!$B:$B,Model!H$3) -> 4 | I13: =COUNTIFS('data set'!$E:$E,Model!$A13,'data set'!$B:$B,Model!I$3) -> 6 | J13: =ROUND(I$15*J24,0) -> 2 | K13: =ROUND(J$15*K24,0) -> 2 | L13: =ROUND(K$15*L24,0) -> 2 | M13: =ROUND(L$15*M24,0) -> 3 | N13: =ROUND(M$15*N24,0) -> 3 | O13: =ROUND(N$15*O24,0) -> 3 | P13: =ROUND(O$15*P24,0) -> 4 | Q13: =ROUND(P$15*Q24,0) -> 4 | S13: =IFERROR(RATE(MONTH($Q$3)-MONTH($I$3),0,-I13,Q13),"N/A") -> -0.049420175 | T13: =IFERROR(RATE(MONTH($Q$3)-MONTH($K$3),0,-K13,Q13),"N/A") -> 0.12246205
A14: Total Churn | B14: =SUM(B12:B13) -> 0 | C14: =SUM(C12:C13) -> 1 | D14: =SUM(D12:D13) -> 2 | E14: =SUM(E12:E13) -> 3 | F14: =SUM(F12:F13) -> 3 | G14: =SUM(G12:G13) -> 6 | H14: =SUM(H12:H13) -> 5 | I14: =SUM(I12:I13) -> 7 | ... Q14: =SUM(Q12:Q13) -> 8 | S14: =IFERROR(RATE(MONTH($Q$3)-MONTH($I$3),0,-I14,Q14),"N/A") -> 0.016831504 | T14: =IFERROR(RATE(MONTH($Q$3)-MONTH($K$3),0,-K14,Q14),"N/A") -> 0.12246205
A15: Total Customers | B15: =B11-B14 -> 2 | C15: =C11-C14 -> 27 | D15: =D11-D14 -> 93 | E15: =E11-E14 -> 182 | F15: =F11-F14 -> 234 | G15: =G11-G14 -> 277 | H15: =H11-H14 -> 323 | I15: =I11-I14 -> 372 | ... Q15: =Q11-Q14 -> 898 | S15: =IFERROR(RATE(MONTH($Q$3)-MONTH($I$3),0,-I15,Q15),"N/A") -> 0.11645616 | T15: =IFERROR(RATE(MONTH($Q$3)-MONTH($K$3),0,-K15,Q15),"N/A") -> 0.10362109
A17: Inputs/Assumptions
A18: New | B18: =B4 -> 2 | C18: =C4 -> 26 | D18: =D4 -> 62 | E18: =E4 -> 85 | F18: =F4 -> 51 | G18: =G4 -> 50 | H18: =H4 -> 61 | I18: =I4 -> 64 | J18: =Inputs!B9 -> 62 | K18: =ROUND(J18*(1+K27),0) -> 64 | L18: =ROUND(K18*(1+L27),0) -> 66 | M18: =ROUND(L18*(1+M27),0) -> 68 | N18: =ROUND(M18*(1+N27),0) -> 70 | O18: =ROUND(N18*(1+O27),0) -> 72 | P18: =ROUND(O18*(1+P27),0) -> 74 | Q18: =ROUND(P18*(1+Q27),0) -> 76 | S18: =IFERROR(RATE(MONTH($Q$3)-MONTH($I$3),0,-I18,Q18),"N/A") -> 0.021713666 | T18: =IFERROR(RATE(MONTH($Q$3)-MONTH($K$3),0,-K18,Q18),"N/A") -> 0.029055827
A19: Legacy to New Team | B19: =B5 -> 0 | C19: =C5 -> 1 | D19: =D5 -> 4 | E19: =E5 -> 4 | F19: =F5 -> 5 | G19: =G5 -> 2 | H19: =H5 -> 1 | I19: =I5 -> 0 | J19: =Inputs!B10 -> 3 | K19: =ROUND(J19*(1+K28),0) -> 3 | L19: =ROUND(K19*(1+L28),0) -> 3 | M19: =ROUND(L19*(1+M28),0) -> 3 | N19: =ROUND(M19*(1+N28),0) -> 3 | O19: =ROUND(N19*(1+O28),0) -> 3 | P19: =ROUND(O19*(1+P28),0) -> 3 | Q19: =ROUND(P19*(1+Q28),0) -> 3 | S19: =IFERROR(RATE(MONTH($Q$3)-MONTH($I$3),0,-I19,Q19),"N/A") -> N/A | T19: =IFERROR(RATE(MONTH($Q$3)-MONTH($K$3),0,-K19,Q19),"N/A") -> 8.3526939e-15
A20: Old Team to New Team | B20: =B9 -> 0 | C20: =C9 -> 0 | D20: =D9 -> 0 | E20: =E9 -> 1 | F20: =F9 -> 0 | G20: =G9 -> 3 | H20: =H9 -> 0 | I20: =I9 -> 1 | J20: =Inputs!B13 -> 1 | K20: =ROUND(J20*(1+K29),0) -> 1 | L20: =ROUND(K20*(1+L29),0) -> 1 | M20: =ROUND(L20*(1+M29),0) -> 1 | N20: =ROUND(M20*(1+N29),0) -> 1 | O20: =ROUND(N20*(1+O29),0) -> 1 | P20: =ROUND(O20*(1+P29),0) -> 1 | Q20: =ROUND(P20*(1+Q29),0) -> 1 | S20: =IFERROR(RATE(MONTH($Q$3)-MONTH($I$3),0,-I20,Q20),"N/A") -> 3.1899074e-12 | T20: =IFERROR(RATE(MONTH($Q$3)-MONTH($K$3),0,-K20,Q20),"N/A") -> 8.2329818e-15
A21: Churn % Assumptions
A22: Churn - Failed Reactiviation % of Churn Failed | C22: =IFERROR(C10/B13,"N/A") -> N/A | D22: =IFERROR(D10/C13,"N/A") -> N/A | E22: =IFERROR(E10/D13,"N/A") -> 0 | F22: =IFERROR(F10/E13,"N/A") -> N/A | G22: =IFERROR(G10/F13,"N/A") -> 0.33333333 | H22: =IFERROR(H10/G13,"N/A") -> 0.33333333 | I22: =IFERROR(I10/H13,"N/A") -> 0 | J22: =Inputs!B14 -> 0.75 | K22: =J22 -> 0.75 | L22: =K22 -> 0.75 | M22: =L22 -> 0.75 | N22: =M22 -> 0.75 | O22: =N22 -> 0.75 | P22: =O22 -> 0.75 | Q22: =P22 -> 0.75 | S22: =IFERROR(RATE(MONTH($Q$3)-MONTH($I$3),0,-I22,Q22),"N/A") -> N/A | T22: =IFERROR(RATE(MONTH($Q$3)-MONTH($K$3),0,-K22,Q22),"N/A") -> 8.3526939e-15
A23: Churn | C23: =C12/B15 -> 0.5 | D23: =D12/C15 -> 0.037037037 | E23: =E12/D15 -> 0.032258065 | F23: =F12/E15 -> 0 | G23: =G12/F15 -> 0.012820513 | H23: =H12/G15 -> 0.0036101083 | I23: =I12/H15 -> 0.0030959752 | J23: =Inputs!B15 -> 0.0048816491 | K23: =J23 -> 0.0048816491 | L23: =K23 -> 0.0048816491 | M23: =L23 -> 0.0048816491 | N23: =M23 -> 0.0048816491 | O23: =N23 -> 0.0048816491 | P23: =O23 -> 0.0048816491 | Q23: =P23 -> 0.0048816491 | S23: =IFERROR(RATE(MONTH($Q$3)-MONTH($I$3),0,-I23,Q23),"N/A") -> 0.058573786 | T23: =IFERROR(RATE(MONTH($Q$3)-MONTH($K$3),0,-K23,Q23),"N/A") -> 8.2611401e-15
A24: Churn-Failed | C24: =C13/B15 -> 0 | D24: =D13/C15 -> 0.037037037 | E24: =E13/D15 -> 0 | F24: =F13/E15 -> 0.016483516 | G24: =G13/F15 -> 0.012820513 | H24: =H13/G15 -> 0.014440433 | I24: =I13/H15 -> 0.018575851 | J24: =Inputs!B16 -> 0.005 | K24: =J24 -> 0.005 | L24: =K24 -> 0.005 | M24: =L24 -> 0.005 | N24: =M24 -> 0.005 | O24: =N24 -> 0.005 | P24: =O24 -> 0.005 | Q24: =P24 -> 0.005 | S24: =IFERROR(RATE(MONTH($Q$3)-MONTH($I$3),0,-I24,Q24),"N/A") -> -0.15130301 | T24: =IFERROR(RATE(MONTH($Q$3)-MONTH($K$3),0,-K24,Q24),"N/A") -> 8.323296e-15
S25: =IFERROR(RATE(MONTH($Q$3)-MONTH($I$3),0,-I25,Q25),"N/A") -> N/A | T25: =IFERROR(RATE(MONTH($Q$3)-MONTH($K$3),0,-K25,Q25),"N/A") -> N/A
A26: Growth % by Customer base | S26: =IFERROR(RATE(MONTH($Q$3)-MONTH($I$3),0,-I26,Q26),"N/A") -> N/A | T26: =IFERROR(RATE(MONTH($Q$3)-MONTH($K$3),0,-K26,Q26),"N/A") -> N/A
A27: New | C27: =IFERROR((C4-B4)/B4,"N/A") -> 12 | D27: =IFERROR((D4-C4)/C4,"N/A") -> 1.3846154 | E27: =IFERROR((E4-D4)/D4,"N/A") -> 0.37096774 | F27: =IFERROR((F4-E4)/E4,"N/A") -> -0.4 | G27: =IFERROR((G4-F4)/F4,"N/A") -> -0.019607843 | H27: =IFERROR((H4-G4)/G4,"N/A") -> 0.22 | I27: =IFERROR((I4-H4)/H4,"N/A") -> 0.049180328 | J27: =Inputs!B19 -> 0.03 | K27: =J27 -> 0.03 | L27: =K27 -> 0.03 | M27: =L27 -> 0.03 | N27: =M27 -> 0.03 | O27: =N27 -> 0.03 | P27: =O27 -> 0.03 | Q27: =P27 -> 0.03 | S27: =IFERROR(RATE(MONTH($Q$3)-MONTH($I$3),0,-I27,Q27),"N/A") -> -0.059916935 | T27: =IFERROR(RATE(MONTH($Q$3)-MONTH($K$3),0,-K27,Q27),"N/A") -> 8.2402099e-15
A28: Legacy to New Team | C28: =IFERROR((C5-B5)/B5,"N/A") -> N/A | D28: =IFERROR((D5-C5)/C5,"N/A") -> 3 | E28: =IFERROR((E5-D5)/D5,"N/A") -> 0 | F28: =IFERROR((F5-E5)/E5,"N/A") -> 0.25 | G28: =IFERROR((G5-F5)/F5,"N/A") -> -0.6 | H28: =IFERROR((H5-G5)/G5,"N/A") -> -0.5 | I28: =IFERROR((I5-H5)/H5,"N/A") -> -1 | J28: =Inputs!B20 -> 0 | K28: =J28 -> 0 | L28: =K28 -> 0 | M28: =L28 -> 0 | N28: =M28 -> 0 | O28: =N28 -> 0 | P28: =O28 -> 0 | Q28: =P28 -> 0 | S28: =IFERROR(RATE(MONTH($Q$3)-MONTH($I$3),0,-I28,Q28),"N/A") -> -0.999999 | T28: =IFERROR(RATE(MONTH($Q$3)-MONTH($K$3),0,-K28,Q28),"N/A") -> N/A
A29: Old Team to New Team | C29: =IFERROR((C9-B9)/B9,"N/A") -> N/A | D29: =IFERROR((D9-C9)/C9,"N/A") -> N/A | E29: =IFERROR((E9-D9)/D9,"N/A") -> N/A | F29: =IFERROR((F9-E9)/E9,"N/A") -> -1 | G29: =IFERROR((G9-F9)/F9,"N/A") -> N/A | H29: =IFERROR((H9-G9)/G9,"N/A") -> -1 | I29: =IFERROR((I9-H9)/H9,"N/A") -> N/A | J29: =Inputs!B21 -> 0 | K29: =J29 -> 0 | L29: =K29 -> 0 | M29: =L29 -> 0 | N29: =M29 -> 0 | O29: =N29 -> 0 | P29: =O29 -> 0 | Q29: =P29 -> 0 | S29: =IFERROR(RATE(MONTH($Q$3)-MONTH($I$3),0,-I29,Q29),"N/A") -> N/A | T29: =IFERROR(RATE(MONTH($Q$3)-MONTH($K$3),0,-K29,Q29),"N/A") -> N/A
A32: Metrics vs. Prior Period unless stated otherwise
A33: Overall Customer growth | C33: =(C15-B15)/B15 -> 12.5 | D33: =(D15-C15)/C15 -> 2.4444444 | E33: =(E15-D15)/D15 -> 0.95698925 | F33: =(F15-E15)/E15 -> 0.28571429 | G33: =(G15-F15)/F15 -> 0.18376068 | H33: =(H15-G15)/G15 -> 0.16606498 | I33: =(I15-H15)/H15 -> 0.15170279 | J33: =(J15-I15)/I15 -> 0.16935484 | ... Q33: =(Q15-P15)/P15 -> 0.085852479 | S33: =IFERROR(RATE(MONTH($Q$3)-MONTH($I$3),0,-I33,Q33),"N/A") -> -0.068688619 | T33: =IFERROR(RATE(MONTH($Q$3)-MONTH($K$3),0,-K33,Q33),"N/A") -> -0.081015046
A34: New Customer growth | C34: =(C4-B4)/B4 -> 12 | D34: =(D4-C4)/C4 -> 1.3846154 | E34: =(E4-D4)/D4 -> 0.37096774 | F34: =(F4-E4)/E4 -> -0.4 | G34: =(G4-F4)/F4 -> -0.019607843 | H34: =(H4-G4)/G4 -> 0.22 | I34: =(I4-H4)/H4 -> 0.049180328 | J34: =(J4-I4)/I4 -> -0.03125 | ... Q34: =(Q4-P4)/P4 -> 0.027027027 | S34: =IFERROR(RATE(MONTH($Q$3)-MONTH($I$3),0,-I34,Q34),"N/A") -> -0.072100679 | T34: =IFERROR(RATE(MONTH($Q$3)-MONTH($K$3),0,-K34,Q34),"N/A") -> -0.029057909
A35: Cumulative Customer Churn (2018) | F35: =F12 -> 0 | G35: =F35+G12 -> 3 | H35: =G35+H12 -> 4 | I35: =H35+I12 -> 5 | J35: =I35+J12 -> 7 | K35: =J35+K12 -> 9 | L35: =K35+L12 -> 11 | M35: =L35+M12 -> 14 | N35: =M35+N12 -> 17 | ... Q35: =P35+Q12 -> 28
A36: % New (# of New Customers/ Total # of Customers) | B36: =B4/B$15 -> 1 | C36: =C4/C$15 -> 0.96296296 | D36: =D4/D$15 -> 0.66666667 | E36: =E4/E$15 -> 0.46703297 | F36: =F4/F$15 -> 0.21794872 | G36: =G4/G$15 -> 0.18050542 | H36: =H4/H$15 -> 0.18885449 | I36: =I4/I$15 -> 0.17204301 | ... Q36: =Q4/Q$15 -> 0.084632517 | S36: =IFERROR(RATE(MONTH($Q$3)-MONTH($I$3),0,-I36,Q36),"N/A") -> -0.084860023 | T36: =IFERROR(RATE(MONTH($Q$3)-MONTH($K$3),0,-K36,Q36),"N/A") -> -0.067564188
A37: % Legacy to New Team | C37: =C5/B$15 -> 0.5 | D37: =D5/C$15 -> 0.14814815 | E37: =E5/D$15 -> 0.043010753 | F37: =F5/E$15 -> 0.027472527 | G37: =G5/F$15 -> 0.0085470085 | H37: =H5/G$15 -> 0.0036101083 | I37: =I5/H$15 -> 0 | J37: =J5/I$15 -> 0.0080645161 | ... Q37: =Q5/P$15 -> 0.0036275695 | S37: =IFERROR(RATE(MONTH($Q$3)-MONTH($I$3),0,-I37,Q37),"N/A") -> N/A | T37: =IFERROR(RATE(MONTH($Q$3)-MONTH($K$3),0,-K37,Q37),"N/A") -> -0.10154301
A38: % Customers that remained same | C38: =C6/B$15 -> 0.5 | D38: =D6/C$15 -> 0.81481481 | E38: =E6/D$15 -> 0.72043011 | F38: =F6/E$15 -> 0.71978022 | G38: =G6/F$15 -> 0.72222222 | H38: =H6/G$15 -> 0.68592058 | I38: =I6/H$15 -> 0.69040248 | J38: =J6/I$15 -> 0.69623656 | ... Q38: =Q6/P$15 -> 0.72430472 | S38: =IFERROR(RATE(MONTH($Q$3)-MONTH($I$3),0,-I38,Q38),"N/A") -> 0.0060101709 | T38: =IFERROR(RATE(MONTH($Q$3)-MONTH($K$3),0,-K38,Q38),"N/A") -> 0.0054298816
A39: % Customers that Expand | C39: =C7/B$15 -> 0 | D39: =D7/C$15 -> 0.18518519 | E39: =E7/D$15 -> 0.15053763 | F39: =F7/E$15 -> 0.13186813 | G39: =G7/F$15 -> 0.18803419 | H39: =H7/G$15 -> 0.14801444 | I39: =I7/H$15 -> 0.18575851 | J39: =J7/I$15 -> 0.18548387 | ... Q39: =Q7/P$15 -> 0.17533253 | S39: =IFERROR(RATE(MONTH($Q$3)-MONTH($I$3),0,-I39,Q39),"N/A") -> -0.0071943945 | T39: =IFERROR(RATE(MONTH($Q$3)-MONTH($K$3),0,-K39,Q39),"N/A") -> -0.0079270069
A40: % Customers that Contracted | C40: =C8/B$15 -> 0 | D40: =D8/C$15 -> 0.074074074 | E40: =E8/D$15 -> 0.15053763 | F40: =F8/E$15 -> 0.14285714 | G40: =G8/F$15 -> 0.05982906 | H40: =H8/G$15 -> 0.12274368 | I40: =I8/H$15 -> 0.095975232 | J40: =J8/I$15 -> 0.10752688 | ... Q40: =Q8/P$15 -> 0.095525998 | S40: =IFERROR(RATE(MONTH($Q$3)-MONTH($I$3),0,-I40,Q40),"N/A") -> -0.00058629354 | T40: =IFERROR(RATE(MONTH($Q$3)-MONTH($K$3),0,-K40,Q40),"N/A") -> -0.016799325
A41: % Old Team to New Team | C41: =C9/B$15 -> 0 | D41: =D9/C$15 -> 0 | E41: =E9/D$15 -> 0.010752688 | F41: =F9/E$15 -> 0 | G41: =G9/F$15 -> 0.012820513 | H41: =H9/G$15 -> 0 | I41: =I9/H$15 -> 0.0030959752 | J41: =J9/I$15 -> 0.002688172 | ... Q41: =Q9/P$15 -> 0.0012091898 | S41: =IFERROR(RATE(MONTH($Q$3)-MONTH($I$3),0,-I41,Q41),"N/A") -> -0.11087642 | T41: =IFERROR(RATE(MONTH($Q$3)-MONTH($K$3),0,-K41,Q41),"N/A") -> -0.10154301
A42: % Failed Churn - Reactivition | C42: =C10/B$15 -> 0 | D42: =D10/C$15 -> 0 | E42: =E10/D$15 -> 0 | F42: =F10/E$15 -> 0 | G42: =G10/F$15 -> 0.0042735043 | H42: =H10/G$15 -> 0.0036101083 | I42: =I10/H$15 -> 0 | J42: =J10/I$15 -> 0.01344086 | ... Q42: =Q10/P$15 -> 0.0036275695 | S42: =IFERROR(RATE(MONTH($Q$3)-MONTH($I$3),0,-I42,Q42),"N/A") -> N/A | T42: =IFERROR(RATE(MONTH($Q$3)-MONTH($K$3),0,-K42,Q42),"N/A") -> -0.038729014
A43: % Churn | C43: =C12/B$15 -> 0.5 | D43: =D12/C$15 -> 0.037037037 | E43: =E12/D$15 -> 0.032258065 | F43: =F12/E$15 -> 0 | G43: =G12/F$15 -> 0.012820513 | H43: =H12/G$15 -> 0.0036101083 | I43: =I12/H$15 -> 0.0030959752 | J43: =J12/I$15 -> 0.0053763441 | ... Q43: =Q12/P$15 -> 0.0048367594 | S43: =IFERROR(RATE(MONTH($Q$3)-MONTH($I$3),0,-I43,Q43),"N/A") -> 0.057352084 | T43: =IFERROR(RATE(MONTH($Q$3)-MONTH($K$3),0,-K43,Q43),"N/A") -> 0.0084838719
A44: % Churn -Failed | C44: =C13/B$15 -> 0 | D44: =D13/C$15 -> 0.037037037 | E44: =E13/D$15 -> 0 | F44: =F13/E$15 -> 0.016483516 | G44: =G13/F$15 -> 0.012820513 | H44: =H13/G$15 -> 0.014440433 | I44: =I13/H$15 -> 0.018575851 | J44: =J13/I$15 -> 0.0053763441 | ... Q44: =Q13/P$15 -> 0.0048367594 | S44: =IFERROR(RATE(MONTH($Q$3)-MONTH($I$3),0,-I44,Q44),"N/A") -> -0.15481707 | T44: =IFERROR(RATE(MONTH($Q$3)-MONTH($K$3),0,-K44,Q44),"N/A") -> 0.0084838719
...

Sheet data set
A1: workspace_id | B1: time_period | C1: start_arr | D1: end_arr | E1: change_type | F1: change_arr
A2: TCQZ2hkxWF | B2: 42979 | C2: 0 | D2: 1200 | E2: New | F2: 1200
A3: M59ojynAVJ | B3: 42979 | C3: 0 | D3: 9804 | E3: New | F3: 9804
A4: M59ojynAVJ | B4: 43009 | C4: 9804 | D4: 0 | E4: Churn | F4: -9804
A5: TCQZ2hkxWF | B5: 43009 | C5: 1200 | D5: 1200 | E5: No Change | F5: 0
A6: SCuDSME3Ff | B6: 43009 | C6: 0 | D6: 1200 | E6: New | F6: 1200
A7: RuFrFxGNyy | B7: 43009 | C7: 0 | D7: 1200 | E7: New | F7: 1200
A8: cEbVUyf5cJ | B8: 43009 | C8: 0 | D8: 1200 | E8: New | F8: 1200
A9: Lxvv14xXR7 | B9: 43009 | C9: 0 | D9: 1440 | E9: New | F9: 1440
A10: L2Br1vbRYT | B10: 43009 | C10: 0 | D10: 1440 | E10: New | F10: 1440
A11: W0oPZYASZG | B11: 43009 | C11: 0 | D11: 1440 | E11: New | F11: 1440
A12: Ik1cIiOBXS | B12: 43009 | C12: 0 | D12: 1440 | E12: New | F12: 1440
A13: fgJgxNEqgy | B13: 43009 | C13: 0 | D13: 1440 | E13: New | F13: 1440
... A1565: 9xnuq0cy33 | B1565: 43191 | C1565: 0 | D1565: 13368 | E1565: New | F1565: 13368

Sheet Growth_Analysis
A1: Linear Equations | B1: Varible | C1: Constant
A2: MoM Customer Growth | B2: 48.3 | C2: 228.5
A3: New | B3: -1.8 | C3: 68.5
A4: Expansion | B4: 10.78 | C4: -6.2
A5: Contraction | B5: 5.6 | C5: 0.7333
B8: Historical | J8: Projected
B9: =Model!B3 -> 42979 | C9: =Model!C3 -> 43009 | D9: =Model!D3 -> 43040 | E9: =Model!E3 -> 43070 | F9: =Model!F3 -> 43101 | G9: =Model!G3 -> 43132 | H9: =Model!H3 -> 43160 | I9: =Model!I3 -> 43191 | ... Q9: =Model!Q3 -> 43435
B10: 0 | C10: 0 | D10: 1 | E10: 2 | F10: 3 | G10: 4 | H10: 5 | I10: 6 | J10: 7 | K10: 8 | L10: 9 | M10: 10 | N10: 11 | O10: 12 | P10: 13 | Q10: 14
A11: MoM Customer growth | B11: =Model!B15 -> 2 | C11: =Model!C15 -> 27 | D11: =Model!D15 -> 93 | E11: =Model!E15 -> 182 | F11: =Model!F15 -> 234 | G11: =Model!G15 -> 277 | H11: =Model!H15 -> 323 | I11: =Model!I15 -> 372 | J11: =ROUND($B2*J$10+$C2,0) -> 567 | K11: =ROUND($B2*K$10+$C2,0) -> 615 | L11: =ROUND($B2*L$10+$C2,0) -> 663 | M11: =ROUND($B2*M$10+$C2,0) -> 712 | N11: =ROUND($B2*N$10+$C2,0) -> 760 | O11: =ROUND($B2*O$10+$C2,0) -> 808 | P11: =ROUND($B2*P$10+$C2,0) -> 856 | Q11: =ROUND($B2*Q$10+$C2,0) -> 905 | R11: Formula
A12: New (# of New Customers/ Total # of Customers) | B12: =Model!B4 -> 2 | C12: =Model!C4 -> 26 | D12: =Model!D4 -> 62 | E12: =Model!E4 -> 85 | F12: =Model!F4 -> 51 | G12: =Model!G4 -> 50 | H12: =Model!H4 -> 61 | I12: =Model!I4 -> 64 | J12: =ROUND($B3*J$10+$C3,0) -> 56 | K12: =ROUND($B3*K$10+$C3,0) -> 54 | L12: =ROUND($B3*L$10+$C3,0) -> 52 | M12: =ROUND($B3*M$10+$C3,0) -> 51 | N12: =ROUND($B3*N$10+$C3,0) -> 49 | O12: =ROUND($B3*O$10+$C3,0) -> 47 | P12: =ROUND($B3*P$10+$C3,0) -> 45 | Q12: =ROUND($B3*Q$10+$C3,0) -> 43 | R12: Constant
A13: Legacy to New Team | B13: =Model!B5 -> 0 | C13: =Model!C5 -> 1 | D13: =Model!D5 -> 4 | E13: =Model!E5 -> 4 | F13: =Model!F5 -> 5 | G13: =Model!G5 -> 2 | H13: =Model!H5 -> 1 | I13: =Model!I5 -> 0 | R13: Input Assumption
A14: Customers that remained same | B14: =Model!B6 -> 0 | C14: =Model!C6 -> 1 | D14: =Model!D6 -> 22 | E14: =Model!E6 -> 67 | F14: =Model!F6 -> 131 | G14: =Model!G6 -> 169 | H14: =Model!H6 -> 190 | I14: =Model!I6 -> 223 | R14: Formula
A15: Customers that Expand | B15: =Model!B7 -> 0 | C15: =Model!C7 -> 0 | D15: =Model!D7 -> 5 | E15: =Model!E7 -> 14 | F15: =Model!F7 -> 24 | G15: =Model!G7 -> 44 | H15: =Model!H7 -> 41 | I15: =Model!I7 -> 60 | J15: =ROUND($B4*J$10+$C4,0) -> 69 | K15: =ROUND($B4*K$10+$C4,0) -> 80 | L15: =ROUND($B4*L$10+$C4,0) -> 91 | M15: =ROUND($B4*M$10+$C4,0) -> 102 | N15: =ROUND($B4*N$10+$C4,0) -> 112 | O15: =ROUND($B4*O$10+$C4,0) -> 123 | P15: =ROUND($B4*P$10+$C4,0) -> 134 | Q15: =ROUND($B4*Q$10+$C4,0) -> 145 | R15: Linear Equation
A16: Customers that Contracted | B16: =Model!B8 -> 0 | C16: =Model!C8 -> 0 | D16: =Model!D8 -> 2 | E16: =Model!E8 -> 14 | F16: =Model!F8 -> 26 | G16: =Model!G8 -> 14 | H16: =Model!H8 -> 34 | I16: =Model!I8 -> 31 | J16: =ROUND($B5*J$10+$C5,0) -> 40 | K16: =ROUND($B5*K$10+$C5,0) -> 46 | L16: =ROUND($B5*L$10+$C5,0) -> 51 | M16: =ROUND($B5*M$10+$C5,0) -> 57 | N16: =ROUND($B5*N$10+$C5,0) -> 62 | O16: =ROUND($B5*O$10+$C5,0) -> 68 | P16: =ROUND($B5*P$10+$C5,0) -> 74 | Q16: =ROUND($B5*Q$10+$C5,0) -> 79 | R16: Linear Equation
A17: Old Team to New Team | B17: =Model!B9 -> 0 | C17: =Model!C9 -> 0 | D17: =Model!D9 -> 0 | E17: =Model!E9 -> 1 | F17: =Model!F9 -> 0 | G17: =Model!G9 -> 3 | H17: =Model!H9 -> 0 | I17: =Model!I9 -> 1 | R17: Input Assumption
A18: Failed Churn - Reactivition | B18: =Model!B10 -> 0 | C18: =Model!C10 -> 0 | D18: =Model!D10 -> 0 | E18: =Model!E10 -> 0 | F18: =Model!F10 -> 0 | G18: =Model!G10 -> 1 | H18: =Model!H10 -> 1 | I18: =Model!I10 -> 0 | R18: Input Assumption
A19: Churn | B19: =Model!B12 -> 0 | C19: =Model!C12 -> 1 | D19: =Model!D12 -> 1 | E19: =Model!E12 -> 3 | F19: =Model!F12 -> 0 | G19: =Model!G12 -> 3 | H19: =Model!H12 -> 1 | I19: =Model!I12 -> 1 | R19: Input Assumption
A20: Churn -Failed | B20: =Model!B13 -> 0 | C20: =Model!C13 -> 0 | D20: =Model!D13 -> 1 | E20: =Model!E13 -> 0 | F20: =Model!F13 -> 3 | G20: =Model!G13 -> 3 | H20: =Model!H13 -> 4 | I20: =Model!I13 -> 6 | R20: Input Assumption
A21: Churn | B21: =Model!B14 -> 0 | C21: =Model!C14 -> 1 | D21: =Model!D14 -> 2 | E21: =Model!E14 -> 3 | F21: =Model!F14 -> 3 | G21: =Model!G14 -> 6 | H21: =Model!H14 -> 5 | I21: =Model!I14 -> 7 | R21: Formula
A23: Linear Regression Analysis

Sheet Notes
A1: Legacy to New Team
A2: What's the difference between Churn, Churn - Failed, Churn - Reactiviation
A3: Old Team to New Team
A5: Churn means no longer a customer
A6: Churn Failed Reactivation is after Churn Failed - Still a customer
A7: Churn Failed is the same as churn
A8: Is there dropped data?
A9: Are there outliers?
A11: Questions
A12: 39NTHthWY3 is this an outlier?
A13: What do you mean by Net Expansion, is that overall ARR growth, or ARR growth due to expansion?
A15: Methodology 1
... A30: Removed client ID# 39NTHthWY3
